[2024-03-18T11:12:51.365+0545] {processor.py:161} INFO - Started process (PID=12381) to work on //home/sarita/Documents/apache-airflow-project/dags/taxi_metrics_dag.py
[2024-03-18T11:12:51.365+0545] {processor.py:830} INFO - Processing file //home/sarita/Documents/apache-airflow-project/dags/taxi_metrics_dag.py for tasks to queue
[2024-03-18T11:12:51.366+0545] {logging_mixin.py:188} INFO - [2024-03-18T11:12:51.366+0545] {dagbag.py:540} INFO - Filling up the DagBag from //home/sarita/Documents/apache-airflow-project/dags/taxi_metrics_dag.py
[2024-03-18T11:12:51.369+0545] {logging_mixin.py:188} INFO - [2024-03-18T11:12:51.368+0545] {dagbag.py:350} ERROR - Failed to import: //home/sarita/Documents/apache-airflow-project/dags/taxi_metrics_dag.py
Traceback (most recent call last):
  File "/home/sarita/Documents/ETLapp/pythonProject/.venv/lib/python3.9/site-packages/airflow/models/dagbag.py", line 346, in parse
    loader.exec_module(new_module)
  File "<frozen importlib._bootstrap_external>", line 855, in exec_module
  File "<frozen importlib._bootstrap>", line 228, in _call_with_frames_removed
  File "//home/sarita/Documents/apache-airflow-project/dags/taxi_metrics_dag.py", line 11, in <module>
    from db_connection import BATCH_SIZE, get_sqlite_connection, get_clickhouse_connection, SQLITE_TABLE
ModuleNotFoundError: No module named 'db_connection'
[2024-03-18T11:12:51.369+0545] {processor.py:842} WARNING - No viable dags retrieved from //home/sarita/Documents/apache-airflow-project/dags/taxi_metrics_dag.py
[2024-03-18T11:12:51.385+0545] {processor.py:183} INFO - Processing //home/sarita/Documents/apache-airflow-project/dags/taxi_metrics_dag.py took 0.023 seconds
[2024-03-18T11:14:04.314+0545] {processor.py:161} INFO - Started process (PID=12478) to work on //home/sarita/Documents/apache-airflow-project/dags/taxi_metrics_dag.py
[2024-03-18T11:14:04.316+0545] {processor.py:830} INFO - Processing file //home/sarita/Documents/apache-airflow-project/dags/taxi_metrics_dag.py for tasks to queue
[2024-03-18T11:14:04.318+0545] {logging_mixin.py:188} INFO - [2024-03-18T11:14:04.317+0545] {dagbag.py:540} INFO - Filling up the DagBag from //home/sarita/Documents/apache-airflow-project/dags/taxi_metrics_dag.py
[2024-03-18T11:14:04.327+0545] {logging_mixin.py:188} INFO - [2024-03-18T11:14:04.325+0545] {dagbag.py:350} ERROR - Failed to import: //home/sarita/Documents/apache-airflow-project/dags/taxi_metrics_dag.py
Traceback (most recent call last):
  File "/home/sarita/Documents/ETLapp/pythonProject/.venv/lib/python3.9/site-packages/airflow/models/dagbag.py", line 346, in parse
    loader.exec_module(new_module)
  File "<frozen importlib._bootstrap_external>", line 855, in exec_module
  File "<frozen importlib._bootstrap>", line 228, in _call_with_frames_removed
  File "//home/sarita/Documents/apache-airflow-project/dags/taxi_metrics_dag.py", line 11, in <module>
    from db_connection import BATCH_SIZE, get_sqlite_connection, get_clickhouse_connection, SQLITE_TABLE
ModuleNotFoundError: No module named 'db_connection'
[2024-03-18T11:14:04.328+0545] {processor.py:842} WARNING - No viable dags retrieved from //home/sarita/Documents/apache-airflow-project/dags/taxi_metrics_dag.py
[2024-03-18T11:14:04.358+0545] {processor.py:183} INFO - Processing //home/sarita/Documents/apache-airflow-project/dags/taxi_metrics_dag.py took 0.046 seconds
[2024-03-18T11:15:02.093+0545] {processor.py:161} INFO - Started process (PID=12634) to work on //home/sarita/Documents/apache-airflow-project/dags/taxi_metrics_dag.py
[2024-03-18T11:15:02.095+0545] {processor.py:830} INFO - Processing file //home/sarita/Documents/apache-airflow-project/dags/taxi_metrics_dag.py for tasks to queue
[2024-03-18T11:15:02.096+0545] {logging_mixin.py:188} INFO - [2024-03-18T11:15:02.096+0545] {dagbag.py:540} INFO - Filling up the DagBag from //home/sarita/Documents/apache-airflow-project/dags/taxi_metrics_dag.py
[2024-03-18T11:15:02.098+0545] {logging_mixin.py:188} INFO - [2024-03-18T11:15:02.098+0545] {dagbag.py:350} ERROR - Failed to import: //home/sarita/Documents/apache-airflow-project/dags/taxi_metrics_dag.py
Traceback (most recent call last):
  File "/home/sarita/Documents/ETLapp/pythonProject/.venv/lib/python3.9/site-packages/airflow/models/dagbag.py", line 346, in parse
    loader.exec_module(new_module)
  File "<frozen importlib._bootstrap_external>", line 855, in exec_module
  File "<frozen importlib._bootstrap>", line 228, in _call_with_frames_removed
  File "//home/sarita/Documents/apache-airflow-project/dags/taxi_metrics_dag.py", line 11, in <module>
    from db_connection import BATCH_SIZE, get_sqlite_connection, get_clickhouse_connection, SQLITE_TABLE
ModuleNotFoundError: No module named 'db_connection'
[2024-03-18T11:15:02.099+0545] {processor.py:842} WARNING - No viable dags retrieved from //home/sarita/Documents/apache-airflow-project/dags/taxi_metrics_dag.py
[2024-03-18T11:15:02.112+0545] {processor.py:183} INFO - Processing //home/sarita/Documents/apache-airflow-project/dags/taxi_metrics_dag.py took 0.021 seconds
[2024-03-18T11:15:52.757+0545] {processor.py:161} INFO - Started process (PID=12828) to work on //home/sarita/Documents/apache-airflow-project/dags/taxi_metrics_dag.py
[2024-03-18T11:15:52.760+0545] {processor.py:830} INFO - Processing file //home/sarita/Documents/apache-airflow-project/dags/taxi_metrics_dag.py for tasks to queue
[2024-03-18T11:15:52.762+0545] {logging_mixin.py:188} INFO - [2024-03-18T11:15:52.761+0545] {dagbag.py:540} INFO - Filling up the DagBag from //home/sarita/Documents/apache-airflow-project/dags/taxi_metrics_dag.py
[2024-03-18T11:15:52.769+0545] {logging_mixin.py:188} INFO - [2024-03-18T11:15:52.767+0545] {dagbag.py:350} ERROR - Failed to import: //home/sarita/Documents/apache-airflow-project/dags/taxi_metrics_dag.py
Traceback (most recent call last):
  File "/home/sarita/Documents/ETLapp/pythonProject/.venv/lib/python3.9/site-packages/airflow/models/dagbag.py", line 346, in parse
    loader.exec_module(new_module)
  File "<frozen importlib._bootstrap_external>", line 855, in exec_module
  File "<frozen importlib._bootstrap>", line 228, in _call_with_frames_removed
  File "//home/sarita/Documents/apache-airflow-project/dags/taxi_metrics_dag.py", line 11, in <module>
    from db_connection import BATCH_SIZE, get_sqlite_connection, get_clickhouse_connection, SQLITE_TABLE
ModuleNotFoundError: No module named 'db_connection'
[2024-03-18T11:15:52.770+0545] {processor.py:842} WARNING - No viable dags retrieved from //home/sarita/Documents/apache-airflow-project/dags/taxi_metrics_dag.py
[2024-03-18T11:15:52.788+0545] {processor.py:183} INFO - Processing //home/sarita/Documents/apache-airflow-project/dags/taxi_metrics_dag.py took 0.036 seconds
[2024-03-18T11:16:46.861+0545] {processor.py:161} INFO - Started process (PID=12910) to work on //home/sarita/Documents/apache-airflow-project/dags/taxi_metrics_dag.py
[2024-03-18T11:16:46.863+0545] {processor.py:830} INFO - Processing file //home/sarita/Documents/apache-airflow-project/dags/taxi_metrics_dag.py for tasks to queue
[2024-03-18T11:16:46.864+0545] {logging_mixin.py:188} INFO - [2024-03-18T11:16:46.864+0545] {dagbag.py:540} INFO - Filling up the DagBag from //home/sarita/Documents/apache-airflow-project/dags/taxi_metrics_dag.py
[2024-03-18T11:16:46.868+0545] {logging_mixin.py:188} INFO - [2024-03-18T11:16:46.867+0545] {dagbag.py:350} ERROR - Failed to import: //home/sarita/Documents/apache-airflow-project/dags/taxi_metrics_dag.py
Traceback (most recent call last):
  File "/home/sarita/Documents/ETLapp/pythonProject/.venv/lib/python3.9/site-packages/airflow/models/dagbag.py", line 346, in parse
    loader.exec_module(new_module)
  File "<frozen importlib._bootstrap_external>", line 855, in exec_module
  File "<frozen importlib._bootstrap>", line 228, in _call_with_frames_removed
  File "//home/sarita/Documents/apache-airflow-project/dags/taxi_metrics_dag.py", line 11, in <module>
    from db_connection import BATCH_SIZE, get_sqlite_connection, get_clickhouse_connection, SQLITE_TABLE
ModuleNotFoundError: No module named 'db_connection'
[2024-03-18T11:16:46.868+0545] {processor.py:842} WARNING - No viable dags retrieved from //home/sarita/Documents/apache-airflow-project/dags/taxi_metrics_dag.py
[2024-03-18T11:16:46.883+0545] {processor.py:183} INFO - Processing //home/sarita/Documents/apache-airflow-project/dags/taxi_metrics_dag.py took 0.026 seconds
[2024-03-18T11:17:40.965+0545] {processor.py:161} INFO - Started process (PID=12978) to work on //home/sarita/Documents/apache-airflow-project/dags/taxi_metrics_dag.py
[2024-03-18T11:17:40.967+0545] {processor.py:830} INFO - Processing file //home/sarita/Documents/apache-airflow-project/dags/taxi_metrics_dag.py for tasks to queue
[2024-03-18T11:17:40.969+0545] {logging_mixin.py:188} INFO - [2024-03-18T11:17:40.968+0545] {dagbag.py:540} INFO - Filling up the DagBag from //home/sarita/Documents/apache-airflow-project/dags/taxi_metrics_dag.py
[2024-03-18T11:17:40.974+0545] {logging_mixin.py:188} INFO - [2024-03-18T11:17:40.973+0545] {dagbag.py:350} ERROR - Failed to import: //home/sarita/Documents/apache-airflow-project/dags/taxi_metrics_dag.py
Traceback (most recent call last):
  File "/home/sarita/Documents/ETLapp/pythonProject/.venv/lib/python3.9/site-packages/airflow/models/dagbag.py", line 346, in parse
    loader.exec_module(new_module)
  File "<frozen importlib._bootstrap_external>", line 855, in exec_module
  File "<frozen importlib._bootstrap>", line 228, in _call_with_frames_removed
  File "//home/sarita/Documents/apache-airflow-project/dags/taxi_metrics_dag.py", line 11, in <module>
    from db_connection import BATCH_SIZE, get_sqlite_connection, get_clickhouse_connection, SQLITE_TABLE
ModuleNotFoundError: No module named 'db_connection'
[2024-03-18T11:17:40.975+0545] {processor.py:842} WARNING - No viable dags retrieved from //home/sarita/Documents/apache-airflow-project/dags/taxi_metrics_dag.py
[2024-03-18T11:17:41.000+0545] {processor.py:183} INFO - Processing //home/sarita/Documents/apache-airflow-project/dags/taxi_metrics_dag.py took 0.040 seconds
[2024-03-18T11:18:33.616+0545] {processor.py:161} INFO - Started process (PID=13042) to work on //home/sarita/Documents/apache-airflow-project/dags/taxi_metrics_dag.py
[2024-03-18T11:18:33.619+0545] {processor.py:830} INFO - Processing file //home/sarita/Documents/apache-airflow-project/dags/taxi_metrics_dag.py for tasks to queue
[2024-03-18T11:18:33.619+0545] {logging_mixin.py:188} INFO - [2024-03-18T11:18:33.619+0545] {dagbag.py:540} INFO - Filling up the DagBag from //home/sarita/Documents/apache-airflow-project/dags/taxi_metrics_dag.py
[2024-03-18T11:18:33.623+0545] {logging_mixin.py:188} INFO - [2024-03-18T11:18:33.622+0545] {dagbag.py:350} ERROR - Failed to import: //home/sarita/Documents/apache-airflow-project/dags/taxi_metrics_dag.py
Traceback (most recent call last):
  File "/home/sarita/Documents/ETLapp/pythonProject/.venv/lib/python3.9/site-packages/airflow/models/dagbag.py", line 346, in parse
    loader.exec_module(new_module)
  File "<frozen importlib._bootstrap_external>", line 855, in exec_module
  File "<frozen importlib._bootstrap>", line 228, in _call_with_frames_removed
  File "//home/sarita/Documents/apache-airflow-project/dags/taxi_metrics_dag.py", line 11, in <module>
    from db_connection import BATCH_SIZE, get_sqlite_connection, get_clickhouse_connection, SQLITE_TABLE
ModuleNotFoundError: No module named 'db_connection'
[2024-03-18T11:18:33.623+0545] {processor.py:842} WARNING - No viable dags retrieved from //home/sarita/Documents/apache-airflow-project/dags/taxi_metrics_dag.py
[2024-03-18T11:18:33.637+0545] {processor.py:183} INFO - Processing //home/sarita/Documents/apache-airflow-project/dags/taxi_metrics_dag.py took 0.022 seconds
[2024-03-18T11:20:20.915+0545] {processor.py:161} INFO - Started process (PID=13168) to work on //home/sarita/Documents/apache-airflow-project/dags/taxi_metrics_dag.py
[2024-03-18T11:20:20.918+0545] {processor.py:830} INFO - Processing file //home/sarita/Documents/apache-airflow-project/dags/taxi_metrics_dag.py for tasks to queue
[2024-03-18T11:20:20.921+0545] {logging_mixin.py:188} INFO - [2024-03-18T11:20:20.920+0545] {dagbag.py:540} INFO - Filling up the DagBag from //home/sarita/Documents/apache-airflow-project/dags/taxi_metrics_dag.py
[2024-03-18T11:20:20.931+0545] {logging_mixin.py:188} INFO - [2024-03-18T11:20:20.929+0545] {dagbag.py:350} ERROR - Failed to import: //home/sarita/Documents/apache-airflow-project/dags/taxi_metrics_dag.py
Traceback (most recent call last):
  File "/home/sarita/Documents/ETLapp/pythonProject/.venv/lib/python3.9/site-packages/airflow/models/dagbag.py", line 346, in parse
    loader.exec_module(new_module)
  File "<frozen importlib._bootstrap_external>", line 855, in exec_module
  File "<frozen importlib._bootstrap>", line 228, in _call_with_frames_removed
  File "//home/sarita/Documents/apache-airflow-project/dags/taxi_metrics_dag.py", line 11, in <module>
    from db_connection import BATCH_SIZE, get_sqlite_connection, get_clickhouse_connection, SQLITE_TABLE
ModuleNotFoundError: No module named 'db_connection'
[2024-03-18T11:20:20.932+0545] {processor.py:842} WARNING - No viable dags retrieved from //home/sarita/Documents/apache-airflow-project/dags/taxi_metrics_dag.py
[2024-03-18T11:20:20.956+0545] {processor.py:183} INFO - Processing //home/sarita/Documents/apache-airflow-project/dags/taxi_metrics_dag.py took 0.049 seconds
[2024-03-18T11:21:23.080+0545] {processor.py:161} INFO - Started process (PID=13276) to work on //home/sarita/Documents/apache-airflow-project/dags/taxi_metrics_dag.py
[2024-03-18T11:21:23.082+0545] {processor.py:830} INFO - Processing file //home/sarita/Documents/apache-airflow-project/dags/taxi_metrics_dag.py for tasks to queue
[2024-03-18T11:21:23.083+0545] {logging_mixin.py:188} INFO - [2024-03-18T11:21:23.083+0545] {dagbag.py:540} INFO - Filling up the DagBag from //home/sarita/Documents/apache-airflow-project/dags/taxi_metrics_dag.py
[2024-03-18T11:21:23.087+0545] {logging_mixin.py:188} INFO - [2024-03-18T11:21:23.086+0545] {dagbag.py:350} ERROR - Failed to import: //home/sarita/Documents/apache-airflow-project/dags/taxi_metrics_dag.py
Traceback (most recent call last):
  File "/home/sarita/Documents/ETLapp/pythonProject/.venv/lib/python3.9/site-packages/airflow/models/dagbag.py", line 346, in parse
    loader.exec_module(new_module)
  File "<frozen importlib._bootstrap_external>", line 855, in exec_module
  File "<frozen importlib._bootstrap>", line 228, in _call_with_frames_removed
  File "//home/sarita/Documents/apache-airflow-project/dags/taxi_metrics_dag.py", line 11, in <module>
    from db_connection import BATCH_SIZE, get_sqlite_connection, get_clickhouse_connection, SQLITE_TABLE
ModuleNotFoundError: No module named 'db_connection'
[2024-03-18T11:21:23.087+0545] {processor.py:842} WARNING - No viable dags retrieved from //home/sarita/Documents/apache-airflow-project/dags/taxi_metrics_dag.py
[2024-03-18T11:21:23.107+0545] {processor.py:183} INFO - Processing //home/sarita/Documents/apache-airflow-project/dags/taxi_metrics_dag.py took 0.029 seconds
[2024-03-18T11:22:23.721+0545] {processor.py:161} INFO - Started process (PID=13364) to work on //home/sarita/Documents/apache-airflow-project/dags/taxi_metrics_dag.py
[2024-03-18T11:22:23.723+0545] {processor.py:830} INFO - Processing file //home/sarita/Documents/apache-airflow-project/dags/taxi_metrics_dag.py for tasks to queue
[2024-03-18T11:22:23.724+0545] {logging_mixin.py:188} INFO - [2024-03-18T11:22:23.724+0545] {dagbag.py:540} INFO - Filling up the DagBag from //home/sarita/Documents/apache-airflow-project/dags/taxi_metrics_dag.py
[2024-03-18T11:22:23.727+0545] {logging_mixin.py:188} INFO - [2024-03-18T11:22:23.726+0545] {dagbag.py:350} ERROR - Failed to import: //home/sarita/Documents/apache-airflow-project/dags/taxi_metrics_dag.py
Traceback (most recent call last):
  File "/home/sarita/Documents/ETLapp/pythonProject/.venv/lib/python3.9/site-packages/airflow/models/dagbag.py", line 346, in parse
    loader.exec_module(new_module)
  File "<frozen importlib._bootstrap_external>", line 855, in exec_module
  File "<frozen importlib._bootstrap>", line 228, in _call_with_frames_removed
  File "//home/sarita/Documents/apache-airflow-project/dags/taxi_metrics_dag.py", line 11, in <module>
    from db_connection import BATCH_SIZE, get_sqlite_connection, get_clickhouse_connection, SQLITE_TABLE
ModuleNotFoundError: No module named 'db_connection'
[2024-03-18T11:22:23.727+0545] {processor.py:842} WARNING - No viable dags retrieved from //home/sarita/Documents/apache-airflow-project/dags/taxi_metrics_dag.py
[2024-03-18T11:22:23.743+0545] {processor.py:183} INFO - Processing //home/sarita/Documents/apache-airflow-project/dags/taxi_metrics_dag.py took 0.024 seconds
[2024-03-18T11:23:15.928+0545] {processor.py:161} INFO - Started process (PID=13429) to work on //home/sarita/Documents/apache-airflow-project/dags/taxi_metrics_dag.py
[2024-03-18T11:23:15.930+0545] {processor.py:830} INFO - Processing file //home/sarita/Documents/apache-airflow-project/dags/taxi_metrics_dag.py for tasks to queue
[2024-03-18T11:23:15.931+0545] {logging_mixin.py:188} INFO - [2024-03-18T11:23:15.931+0545] {dagbag.py:540} INFO - Filling up the DagBag from //home/sarita/Documents/apache-airflow-project/dags/taxi_metrics_dag.py
[2024-03-18T11:23:15.933+0545] {logging_mixin.py:188} INFO - [2024-03-18T11:23:15.933+0545] {dagbag.py:350} ERROR - Failed to import: //home/sarita/Documents/apache-airflow-project/dags/taxi_metrics_dag.py
Traceback (most recent call last):
  File "/home/sarita/Documents/ETLapp/pythonProject/.venv/lib/python3.9/site-packages/airflow/models/dagbag.py", line 346, in parse
    loader.exec_module(new_module)
  File "<frozen importlib._bootstrap_external>", line 855, in exec_module
  File "<frozen importlib._bootstrap>", line 228, in _call_with_frames_removed
  File "//home/sarita/Documents/apache-airflow-project/dags/taxi_metrics_dag.py", line 11, in <module>
    from db_connection import BATCH_SIZE, get_sqlite_connection, get_clickhouse_connection, SQLITE_TABLE
ModuleNotFoundError: No module named 'db_connection'
[2024-03-18T11:23:15.934+0545] {processor.py:842} WARNING - No viable dags retrieved from //home/sarita/Documents/apache-airflow-project/dags/taxi_metrics_dag.py
[2024-03-18T11:23:15.947+0545] {processor.py:183} INFO - Processing //home/sarita/Documents/apache-airflow-project/dags/taxi_metrics_dag.py took 0.021 seconds
[2024-03-18T11:24:12.205+0545] {processor.py:161} INFO - Started process (PID=13506) to work on //home/sarita/Documents/apache-airflow-project/dags/taxi_metrics_dag.py
[2024-03-18T11:24:12.207+0545] {processor.py:830} INFO - Processing file //home/sarita/Documents/apache-airflow-project/dags/taxi_metrics_dag.py for tasks to queue
[2024-03-18T11:24:12.208+0545] {logging_mixin.py:188} INFO - [2024-03-18T11:24:12.207+0545] {dagbag.py:540} INFO - Filling up the DagBag from //home/sarita/Documents/apache-airflow-project/dags/taxi_metrics_dag.py
[2024-03-18T11:24:12.210+0545] {logging_mixin.py:188} INFO - [2024-03-18T11:24:12.210+0545] {dagbag.py:350} ERROR - Failed to import: //home/sarita/Documents/apache-airflow-project/dags/taxi_metrics_dag.py
Traceback (most recent call last):
  File "/home/sarita/Documents/ETLapp/pythonProject/.venv/lib/python3.9/site-packages/airflow/models/dagbag.py", line 346, in parse
    loader.exec_module(new_module)
  File "<frozen importlib._bootstrap_external>", line 855, in exec_module
  File "<frozen importlib._bootstrap>", line 228, in _call_with_frames_removed
  File "//home/sarita/Documents/apache-airflow-project/dags/taxi_metrics_dag.py", line 11, in <module>
    from db_connection import BATCH_SIZE, get_sqlite_connection, get_clickhouse_connection, SQLITE_TABLE
ModuleNotFoundError: No module named 'db_connection'
[2024-03-18T11:24:12.211+0545] {processor.py:842} WARNING - No viable dags retrieved from //home/sarita/Documents/apache-airflow-project/dags/taxi_metrics_dag.py
[2024-03-18T11:24:12.227+0545] {processor.py:183} INFO - Processing //home/sarita/Documents/apache-airflow-project/dags/taxi_metrics_dag.py took 0.023 seconds
[2024-03-18T11:25:04.767+0545] {processor.py:161} INFO - Started process (PID=13668) to work on //home/sarita/Documents/apache-airflow-project/dags/taxi_metrics_dag.py
[2024-03-18T11:25:04.769+0545] {processor.py:830} INFO - Processing file //home/sarita/Documents/apache-airflow-project/dags/taxi_metrics_dag.py for tasks to queue
[2024-03-18T11:25:04.770+0545] {logging_mixin.py:188} INFO - [2024-03-18T11:25:04.770+0545] {dagbag.py:540} INFO - Filling up the DagBag from //home/sarita/Documents/apache-airflow-project/dags/taxi_metrics_dag.py
[2024-03-18T11:25:04.772+0545] {logging_mixin.py:188} INFO - [2024-03-18T11:25:04.772+0545] {dagbag.py:350} ERROR - Failed to import: //home/sarita/Documents/apache-airflow-project/dags/taxi_metrics_dag.py
Traceback (most recent call last):
  File "/home/sarita/Documents/ETLapp/pythonProject/.venv/lib/python3.9/site-packages/airflow/models/dagbag.py", line 346, in parse
    loader.exec_module(new_module)
  File "<frozen importlib._bootstrap_external>", line 855, in exec_module
  File "<frozen importlib._bootstrap>", line 228, in _call_with_frames_removed
  File "//home/sarita/Documents/apache-airflow-project/dags/taxi_metrics_dag.py", line 11, in <module>
    from db_connection import BATCH_SIZE, get_sqlite_connection, get_clickhouse_connection, SQLITE_TABLE
ModuleNotFoundError: No module named 'db_connection'
[2024-03-18T11:25:04.773+0545] {processor.py:842} WARNING - No viable dags retrieved from //home/sarita/Documents/apache-airflow-project/dags/taxi_metrics_dag.py
[2024-03-18T11:25:04.786+0545] {processor.py:183} INFO - Processing //home/sarita/Documents/apache-airflow-project/dags/taxi_metrics_dag.py took 0.021 seconds
[2024-03-18T11:25:58.048+0545] {processor.py:161} INFO - Started process (PID=13748) to work on //home/sarita/Documents/apache-airflow-project/dags/taxi_metrics_dag.py
[2024-03-18T11:25:58.052+0545] {processor.py:830} INFO - Processing file //home/sarita/Documents/apache-airflow-project/dags/taxi_metrics_dag.py for tasks to queue
[2024-03-18T11:25:58.055+0545] {logging_mixin.py:188} INFO - [2024-03-18T11:25:58.054+0545] {dagbag.py:540} INFO - Filling up the DagBag from //home/sarita/Documents/apache-airflow-project/dags/taxi_metrics_dag.py
[2024-03-18T11:25:58.064+0545] {logging_mixin.py:188} INFO - [2024-03-18T11:25:58.062+0545] {dagbag.py:350} ERROR - Failed to import: //home/sarita/Documents/apache-airflow-project/dags/taxi_metrics_dag.py
Traceback (most recent call last):
  File "/home/sarita/Documents/ETLapp/pythonProject/.venv/lib/python3.9/site-packages/airflow/models/dagbag.py", line 346, in parse
    loader.exec_module(new_module)
  File "<frozen importlib._bootstrap_external>", line 855, in exec_module
  File "<frozen importlib._bootstrap>", line 228, in _call_with_frames_removed
  File "//home/sarita/Documents/apache-airflow-project/dags/taxi_metrics_dag.py", line 11, in <module>
    from db_connection import BATCH_SIZE, get_sqlite_connection, get_clickhouse_connection, SQLITE_TABLE
ModuleNotFoundError: No module named 'db_connection'
[2024-03-18T11:25:58.065+0545] {processor.py:842} WARNING - No viable dags retrieved from //home/sarita/Documents/apache-airflow-project/dags/taxi_metrics_dag.py
[2024-03-18T11:25:58.085+0545] {processor.py:183} INFO - Processing //home/sarita/Documents/apache-airflow-project/dags/taxi_metrics_dag.py took 0.045 seconds
[2024-03-18T11:26:54.525+0545] {processor.py:161} INFO - Started process (PID=14286) to work on //home/sarita/Documents/apache-airflow-project/dags/taxi_metrics_dag.py
[2024-03-18T11:26:54.527+0545] {processor.py:830} INFO - Processing file //home/sarita/Documents/apache-airflow-project/dags/taxi_metrics_dag.py for tasks to queue
[2024-03-18T11:26:54.530+0545] {logging_mixin.py:188} INFO - [2024-03-18T11:26:54.529+0545] {dagbag.py:540} INFO - Filling up the DagBag from //home/sarita/Documents/apache-airflow-project/dags/taxi_metrics_dag.py
[2024-03-18T11:26:54.540+0545] {logging_mixin.py:188} INFO - [2024-03-18T11:26:54.538+0545] {dagbag.py:350} ERROR - Failed to import: //home/sarita/Documents/apache-airflow-project/dags/taxi_metrics_dag.py
Traceback (most recent call last):
  File "/home/sarita/Documents/ETLapp/pythonProject/.venv/lib/python3.9/site-packages/airflow/models/dagbag.py", line 346, in parse
    loader.exec_module(new_module)
  File "<frozen importlib._bootstrap_external>", line 855, in exec_module
  File "<frozen importlib._bootstrap>", line 228, in _call_with_frames_removed
  File "//home/sarita/Documents/apache-airflow-project/dags/taxi_metrics_dag.py", line 11, in <module>
    from db_connection import BATCH_SIZE, get_sqlite_connection, get_clickhouse_connection, SQLITE_TABLE
ModuleNotFoundError: No module named 'db_connection'
[2024-03-18T11:26:54.541+0545] {processor.py:842} WARNING - No viable dags retrieved from //home/sarita/Documents/apache-airflow-project/dags/taxi_metrics_dag.py
[2024-03-18T11:26:54.569+0545] {processor.py:183} INFO - Processing //home/sarita/Documents/apache-airflow-project/dags/taxi_metrics_dag.py took 0.046 seconds
[2024-03-18T11:27:49.258+0545] {processor.py:161} INFO - Started process (PID=14505) to work on //home/sarita/Documents/apache-airflow-project/dags/taxi_metrics_dag.py
[2024-03-18T11:27:49.261+0545] {processor.py:830} INFO - Processing file //home/sarita/Documents/apache-airflow-project/dags/taxi_metrics_dag.py for tasks to queue
[2024-03-18T11:27:49.262+0545] {logging_mixin.py:188} INFO - [2024-03-18T11:27:49.262+0545] {dagbag.py:540} INFO - Filling up the DagBag from //home/sarita/Documents/apache-airflow-project/dags/taxi_metrics_dag.py
[2024-03-18T11:27:49.266+0545] {logging_mixin.py:188} INFO - [2024-03-18T11:27:49.265+0545] {dagbag.py:350} ERROR - Failed to import: //home/sarita/Documents/apache-airflow-project/dags/taxi_metrics_dag.py
Traceback (most recent call last):
  File "/home/sarita/Documents/ETLapp/pythonProject/.venv/lib/python3.9/site-packages/airflow/models/dagbag.py", line 346, in parse
    loader.exec_module(new_module)
  File "<frozen importlib._bootstrap_external>", line 855, in exec_module
  File "<frozen importlib._bootstrap>", line 228, in _call_with_frames_removed
  File "//home/sarita/Documents/apache-airflow-project/dags/taxi_metrics_dag.py", line 11, in <module>
    from db_connection import BATCH_SIZE, get_sqlite_connection, get_clickhouse_connection, SQLITE_TABLE
ModuleNotFoundError: No module named 'db_connection'
[2024-03-18T11:27:49.266+0545] {processor.py:842} WARNING - No viable dags retrieved from //home/sarita/Documents/apache-airflow-project/dags/taxi_metrics_dag.py
[2024-03-18T11:27:49.282+0545] {processor.py:183} INFO - Processing //home/sarita/Documents/apache-airflow-project/dags/taxi_metrics_dag.py took 0.027 seconds
[2024-03-18T11:28:43.946+0545] {processor.py:161} INFO - Started process (PID=14642) to work on //home/sarita/Documents/apache-airflow-project/dags/taxi_metrics_dag.py
[2024-03-18T11:28:43.948+0545] {processor.py:830} INFO - Processing file //home/sarita/Documents/apache-airflow-project/dags/taxi_metrics_dag.py for tasks to queue
[2024-03-18T11:28:43.950+0545] {logging_mixin.py:188} INFO - [2024-03-18T11:28:43.949+0545] {dagbag.py:540} INFO - Filling up the DagBag from //home/sarita/Documents/apache-airflow-project/dags/taxi_metrics_dag.py
[2024-03-18T11:28:43.954+0545] {logging_mixin.py:188} INFO - [2024-03-18T11:28:43.953+0545] {dagbag.py:350} ERROR - Failed to import: //home/sarita/Documents/apache-airflow-project/dags/taxi_metrics_dag.py
Traceback (most recent call last):
  File "/home/sarita/Documents/ETLapp/pythonProject/.venv/lib/python3.9/site-packages/airflow/models/dagbag.py", line 346, in parse
    loader.exec_module(new_module)
  File "<frozen importlib._bootstrap_external>", line 855, in exec_module
  File "<frozen importlib._bootstrap>", line 228, in _call_with_frames_removed
  File "//home/sarita/Documents/apache-airflow-project/dags/taxi_metrics_dag.py", line 11, in <module>
    from db_connection import BATCH_SIZE, get_sqlite_connection, get_clickhouse_connection, SQLITE_TABLE
ModuleNotFoundError: No module named 'db_connection'
[2024-03-18T11:28:43.954+0545] {processor.py:842} WARNING - No viable dags retrieved from //home/sarita/Documents/apache-airflow-project/dags/taxi_metrics_dag.py
[2024-03-18T11:28:43.973+0545] {processor.py:183} INFO - Processing //home/sarita/Documents/apache-airflow-project/dags/taxi_metrics_dag.py took 0.030 seconds
[2024-03-18T11:29:40.155+0545] {processor.py:161} INFO - Started process (PID=14707) to work on //home/sarita/Documents/apache-airflow-project/dags/taxi_metrics_dag.py
[2024-03-18T11:29:40.157+0545] {processor.py:830} INFO - Processing file //home/sarita/Documents/apache-airflow-project/dags/taxi_metrics_dag.py for tasks to queue
[2024-03-18T11:29:40.157+0545] {logging_mixin.py:188} INFO - [2024-03-18T11:29:40.157+0545] {dagbag.py:540} INFO - Filling up the DagBag from //home/sarita/Documents/apache-airflow-project/dags/taxi_metrics_dag.py
[2024-03-18T11:29:40.160+0545] {logging_mixin.py:188} INFO - [2024-03-18T11:29:40.159+0545] {dagbag.py:350} ERROR - Failed to import: //home/sarita/Documents/apache-airflow-project/dags/taxi_metrics_dag.py
Traceback (most recent call last):
  File "/home/sarita/Documents/ETLapp/pythonProject/.venv/lib/python3.9/site-packages/airflow/models/dagbag.py", line 346, in parse
    loader.exec_module(new_module)
  File "<frozen importlib._bootstrap_external>", line 855, in exec_module
  File "<frozen importlib._bootstrap>", line 228, in _call_with_frames_removed
  File "//home/sarita/Documents/apache-airflow-project/dags/taxi_metrics_dag.py", line 11, in <module>
    from db_connection import BATCH_SIZE, get_sqlite_connection, get_clickhouse_connection, SQLITE_TABLE
ModuleNotFoundError: No module named 'db_connection'
[2024-03-18T11:29:40.160+0545] {processor.py:842} WARNING - No viable dags retrieved from //home/sarita/Documents/apache-airflow-project/dags/taxi_metrics_dag.py
[2024-03-18T11:29:40.175+0545] {processor.py:183} INFO - Processing //home/sarita/Documents/apache-airflow-project/dags/taxi_metrics_dag.py took 0.022 seconds
[2024-03-18T11:30:36.383+0545] {processor.py:161} INFO - Started process (PID=14820) to work on //home/sarita/Documents/apache-airflow-project/dags/taxi_metrics_dag.py
[2024-03-18T11:30:36.385+0545] {processor.py:830} INFO - Processing file //home/sarita/Documents/apache-airflow-project/dags/taxi_metrics_dag.py for tasks to queue
[2024-03-18T11:30:36.387+0545] {logging_mixin.py:188} INFO - [2024-03-18T11:30:36.386+0545] {dagbag.py:540} INFO - Filling up the DagBag from //home/sarita/Documents/apache-airflow-project/dags/taxi_metrics_dag.py
[2024-03-18T11:30:36.392+0545] {logging_mixin.py:188} INFO - [2024-03-18T11:30:36.391+0545] {dagbag.py:350} ERROR - Failed to import: //home/sarita/Documents/apache-airflow-project/dags/taxi_metrics_dag.py
Traceback (most recent call last):
  File "/home/sarita/Documents/ETLapp/pythonProject/.venv/lib/python3.9/site-packages/airflow/models/dagbag.py", line 346, in parse
    loader.exec_module(new_module)
  File "<frozen importlib._bootstrap_external>", line 855, in exec_module
  File "<frozen importlib._bootstrap>", line 228, in _call_with_frames_removed
  File "//home/sarita/Documents/apache-airflow-project/dags/taxi_metrics_dag.py", line 11, in <module>
    from db_connection import BATCH_SIZE, get_sqlite_connection, get_clickhouse_connection, SQLITE_TABLE
ModuleNotFoundError: No module named 'db_connection'
[2024-03-18T11:30:36.393+0545] {processor.py:842} WARNING - No viable dags retrieved from //home/sarita/Documents/apache-airflow-project/dags/taxi_metrics_dag.py
[2024-03-18T11:30:36.417+0545] {processor.py:183} INFO - Processing //home/sarita/Documents/apache-airflow-project/dags/taxi_metrics_dag.py took 0.039 seconds
[2024-03-18T11:31:31.529+0545] {processor.py:161} INFO - Started process (PID=14930) to work on //home/sarita/Documents/apache-airflow-project/dags/taxi_metrics_dag.py
[2024-03-18T11:31:31.533+0545] {processor.py:830} INFO - Processing file //home/sarita/Documents/apache-airflow-project/dags/taxi_metrics_dag.py for tasks to queue
[2024-03-18T11:31:31.536+0545] {logging_mixin.py:188} INFO - [2024-03-18T11:31:31.535+0545] {dagbag.py:540} INFO - Filling up the DagBag from //home/sarita/Documents/apache-airflow-project/dags/taxi_metrics_dag.py
[2024-03-18T11:31:31.546+0545] {logging_mixin.py:188} INFO - [2024-03-18T11:31:31.543+0545] {dagbag.py:350} ERROR - Failed to import: //home/sarita/Documents/apache-airflow-project/dags/taxi_metrics_dag.py
Traceback (most recent call last):
  File "/home/sarita/Documents/ETLapp/pythonProject/.venv/lib/python3.9/site-packages/airflow/models/dagbag.py", line 346, in parse
    loader.exec_module(new_module)
  File "<frozen importlib._bootstrap_external>", line 855, in exec_module
  File "<frozen importlib._bootstrap>", line 228, in _call_with_frames_removed
  File "//home/sarita/Documents/apache-airflow-project/dags/taxi_metrics_dag.py", line 11, in <module>
    from db_connection import BATCH_SIZE, get_sqlite_connection, get_clickhouse_connection, SQLITE_TABLE
ModuleNotFoundError: No module named 'db_connection'
[2024-03-18T11:31:31.547+0545] {processor.py:842} WARNING - No viable dags retrieved from //home/sarita/Documents/apache-airflow-project/dags/taxi_metrics_dag.py
[2024-03-18T11:31:31.568+0545] {processor.py:183} INFO - Processing //home/sarita/Documents/apache-airflow-project/dags/taxi_metrics_dag.py took 0.047 seconds
[2024-03-18T11:32:28.202+0545] {processor.py:161} INFO - Started process (PID=15047) to work on //home/sarita/Documents/apache-airflow-project/dags/taxi_metrics_dag.py
[2024-03-18T11:32:28.206+0545] {processor.py:830} INFO - Processing file //home/sarita/Documents/apache-airflow-project/dags/taxi_metrics_dag.py for tasks to queue
[2024-03-18T11:32:28.209+0545] {logging_mixin.py:188} INFO - [2024-03-18T11:32:28.208+0545] {dagbag.py:540} INFO - Filling up the DagBag from //home/sarita/Documents/apache-airflow-project/dags/taxi_metrics_dag.py
[2024-03-18T11:32:28.219+0545] {logging_mixin.py:188} INFO - [2024-03-18T11:32:28.217+0545] {dagbag.py:350} ERROR - Failed to import: //home/sarita/Documents/apache-airflow-project/dags/taxi_metrics_dag.py
Traceback (most recent call last):
  File "/home/sarita/Documents/ETLapp/pythonProject/.venv/lib/python3.9/site-packages/airflow/models/dagbag.py", line 346, in parse
    loader.exec_module(new_module)
  File "<frozen importlib._bootstrap_external>", line 855, in exec_module
  File "<frozen importlib._bootstrap>", line 228, in _call_with_frames_removed
  File "//home/sarita/Documents/apache-airflow-project/dags/taxi_metrics_dag.py", line 11, in <module>
    from db_connection import BATCH_SIZE, get_sqlite_connection, get_clickhouse_connection, SQLITE_TABLE
ModuleNotFoundError: No module named 'db_connection'
[2024-03-18T11:32:28.220+0545] {processor.py:842} WARNING - No viable dags retrieved from //home/sarita/Documents/apache-airflow-project/dags/taxi_metrics_dag.py
[2024-03-18T11:32:28.241+0545] {processor.py:183} INFO - Processing //home/sarita/Documents/apache-airflow-project/dags/taxi_metrics_dag.py took 0.046 seconds
[2024-03-18T11:34:14.986+0545] {processor.py:161} INFO - Started process (PID=15225) to work on //home/sarita/Documents/apache-airflow-project/dags/taxi_metrics_dag.py
[2024-03-18T11:34:14.988+0545] {processor.py:830} INFO - Processing file //home/sarita/Documents/apache-airflow-project/dags/taxi_metrics_dag.py for tasks to queue
[2024-03-18T11:34:14.989+0545] {logging_mixin.py:188} INFO - [2024-03-18T11:34:14.988+0545] {dagbag.py:540} INFO - Filling up the DagBag from //home/sarita/Documents/apache-airflow-project/dags/taxi_metrics_dag.py
[2024-03-18T11:34:14.991+0545] {logging_mixin.py:188} INFO - [2024-03-18T11:34:14.990+0545] {dagbag.py:350} ERROR - Failed to import: //home/sarita/Documents/apache-airflow-project/dags/taxi_metrics_dag.py
Traceback (most recent call last):
  File "/home/sarita/Documents/ETLapp/pythonProject/.venv/lib/python3.9/site-packages/airflow/models/dagbag.py", line 346, in parse
    loader.exec_module(new_module)
  File "<frozen importlib._bootstrap_external>", line 855, in exec_module
  File "<frozen importlib._bootstrap>", line 228, in _call_with_frames_removed
  File "//home/sarita/Documents/apache-airflow-project/dags/taxi_metrics_dag.py", line 11, in <module>
    from db_connection import BATCH_SIZE, get_sqlite_connection, get_clickhouse_connection, SQLITE_TABLE
ModuleNotFoundError: No module named 'db_connection'
[2024-03-18T11:34:14.991+0545] {processor.py:842} WARNING - No viable dags retrieved from //home/sarita/Documents/apache-airflow-project/dags/taxi_metrics_dag.py
[2024-03-18T11:34:15.003+0545] {processor.py:183} INFO - Processing //home/sarita/Documents/apache-airflow-project/dags/taxi_metrics_dag.py took 0.019 seconds
[2024-03-18T11:35:12.576+0545] {processor.py:161} INFO - Started process (PID=15379) to work on //home/sarita/Documents/apache-airflow-project/dags/taxi_metrics_dag.py
[2024-03-18T11:35:12.579+0545] {processor.py:830} INFO - Processing file //home/sarita/Documents/apache-airflow-project/dags/taxi_metrics_dag.py for tasks to queue
[2024-03-18T11:35:12.582+0545] {logging_mixin.py:188} INFO - [2024-03-18T11:35:12.581+0545] {dagbag.py:540} INFO - Filling up the DagBag from //home/sarita/Documents/apache-airflow-project/dags/taxi_metrics_dag.py
[2024-03-18T11:35:12.592+0545] {logging_mixin.py:188} INFO - [2024-03-18T11:35:12.590+0545] {dagbag.py:350} ERROR - Failed to import: //home/sarita/Documents/apache-airflow-project/dags/taxi_metrics_dag.py
Traceback (most recent call last):
  File "/home/sarita/Documents/ETLapp/pythonProject/.venv/lib/python3.9/site-packages/airflow/models/dagbag.py", line 346, in parse
    loader.exec_module(new_module)
  File "<frozen importlib._bootstrap_external>", line 855, in exec_module
  File "<frozen importlib._bootstrap>", line 228, in _call_with_frames_removed
  File "//home/sarita/Documents/apache-airflow-project/dags/taxi_metrics_dag.py", line 11, in <module>
    from db_connection import BATCH_SIZE, get_sqlite_connection, get_clickhouse_connection, SQLITE_TABLE
ModuleNotFoundError: No module named 'db_connection'
[2024-03-18T11:35:12.593+0545] {processor.py:842} WARNING - No viable dags retrieved from //home/sarita/Documents/apache-airflow-project/dags/taxi_metrics_dag.py
[2024-03-18T11:35:12.615+0545] {processor.py:183} INFO - Processing //home/sarita/Documents/apache-airflow-project/dags/taxi_metrics_dag.py took 0.047 seconds
[2024-03-18T11:36:15.771+0545] {processor.py:161} INFO - Started process (PID=15459) to work on //home/sarita/Documents/apache-airflow-project/dags/taxi_metrics_dag.py
[2024-03-18T11:36:15.773+0545] {processor.py:830} INFO - Processing file //home/sarita/Documents/apache-airflow-project/dags/taxi_metrics_dag.py for tasks to queue
[2024-03-18T11:36:15.773+0545] {logging_mixin.py:188} INFO - [2024-03-18T11:36:15.773+0545] {dagbag.py:540} INFO - Filling up the DagBag from //home/sarita/Documents/apache-airflow-project/dags/taxi_metrics_dag.py
[2024-03-18T11:36:15.776+0545] {logging_mixin.py:188} INFO - [2024-03-18T11:36:15.775+0545] {dagbag.py:350} ERROR - Failed to import: //home/sarita/Documents/apache-airflow-project/dags/taxi_metrics_dag.py
Traceback (most recent call last):
  File "/home/sarita/Documents/ETLapp/pythonProject/.venv/lib/python3.9/site-packages/airflow/models/dagbag.py", line 346, in parse
    loader.exec_module(new_module)
  File "<frozen importlib._bootstrap_external>", line 855, in exec_module
  File "<frozen importlib._bootstrap>", line 228, in _call_with_frames_removed
  File "//home/sarita/Documents/apache-airflow-project/dags/taxi_metrics_dag.py", line 11, in <module>
    from db_connection import BATCH_SIZE, get_sqlite_connection, get_clickhouse_connection, SQLITE_TABLE
ModuleNotFoundError: No module named 'db_connection'
[2024-03-18T11:36:15.776+0545] {processor.py:842} WARNING - No viable dags retrieved from //home/sarita/Documents/apache-airflow-project/dags/taxi_metrics_dag.py
[2024-03-18T11:36:15.789+0545] {processor.py:183} INFO - Processing //home/sarita/Documents/apache-airflow-project/dags/taxi_metrics_dag.py took 0.021 seconds
[2024-03-18T11:37:14.142+0545] {processor.py:161} INFO - Started process (PID=15534) to work on //home/sarita/Documents/apache-airflow-project/dags/taxi_metrics_dag.py
[2024-03-18T11:37:14.146+0545] {processor.py:830} INFO - Processing file //home/sarita/Documents/apache-airflow-project/dags/taxi_metrics_dag.py for tasks to queue
[2024-03-18T11:37:14.149+0545] {logging_mixin.py:188} INFO - [2024-03-18T11:37:14.147+0545] {dagbag.py:540} INFO - Filling up the DagBag from //home/sarita/Documents/apache-airflow-project/dags/taxi_metrics_dag.py
[2024-03-18T11:37:14.158+0545] {logging_mixin.py:188} INFO - [2024-03-18T11:37:14.156+0545] {dagbag.py:350} ERROR - Failed to import: //home/sarita/Documents/apache-airflow-project/dags/taxi_metrics_dag.py
Traceback (most recent call last):
  File "/home/sarita/Documents/ETLapp/pythonProject/.venv/lib/python3.9/site-packages/airflow/models/dagbag.py", line 346, in parse
    loader.exec_module(new_module)
  File "<frozen importlib._bootstrap_external>", line 855, in exec_module
  File "<frozen importlib._bootstrap>", line 228, in _call_with_frames_removed
  File "//home/sarita/Documents/apache-airflow-project/dags/taxi_metrics_dag.py", line 11, in <module>
    from db_connection import BATCH_SIZE, get_sqlite_connection, get_clickhouse_connection, SQLITE_TABLE
ModuleNotFoundError: No module named 'db_connection'
[2024-03-18T11:37:14.158+0545] {processor.py:842} WARNING - No viable dags retrieved from //home/sarita/Documents/apache-airflow-project/dags/taxi_metrics_dag.py
[2024-03-18T11:37:14.180+0545] {processor.py:183} INFO - Processing //home/sarita/Documents/apache-airflow-project/dags/taxi_metrics_dag.py took 0.046 seconds
[2024-03-18T11:38:08.796+0545] {processor.py:161} INFO - Started process (PID=15636) to work on //home/sarita/Documents/apache-airflow-project/dags/taxi_metrics_dag.py
[2024-03-18T11:38:08.798+0545] {processor.py:830} INFO - Processing file //home/sarita/Documents/apache-airflow-project/dags/taxi_metrics_dag.py for tasks to queue
[2024-03-18T11:38:08.799+0545] {logging_mixin.py:188} INFO - [2024-03-18T11:38:08.799+0545] {dagbag.py:540} INFO - Filling up the DagBag from //home/sarita/Documents/apache-airflow-project/dags/taxi_metrics_dag.py
[2024-03-18T11:38:08.802+0545] {logging_mixin.py:188} INFO - [2024-03-18T11:38:08.801+0545] {dagbag.py:350} ERROR - Failed to import: //home/sarita/Documents/apache-airflow-project/dags/taxi_metrics_dag.py
Traceback (most recent call last):
  File "/home/sarita/Documents/ETLapp/pythonProject/.venv/lib/python3.9/site-packages/airflow/models/dagbag.py", line 346, in parse
    loader.exec_module(new_module)
  File "<frozen importlib._bootstrap_external>", line 855, in exec_module
  File "<frozen importlib._bootstrap>", line 228, in _call_with_frames_removed
  File "//home/sarita/Documents/apache-airflow-project/dags/taxi_metrics_dag.py", line 11, in <module>
    from db_connection import BATCH_SIZE, get_sqlite_connection, get_clickhouse_connection, SQLITE_TABLE
ModuleNotFoundError: No module named 'db_connection'
[2024-03-18T11:38:08.802+0545] {processor.py:842} WARNING - No viable dags retrieved from //home/sarita/Documents/apache-airflow-project/dags/taxi_metrics_dag.py
[2024-03-18T11:38:08.816+0545] {processor.py:183} INFO - Processing //home/sarita/Documents/apache-airflow-project/dags/taxi_metrics_dag.py took 0.022 seconds
[2024-03-18T11:39:02.421+0545] {processor.py:161} INFO - Started process (PID=15708) to work on //home/sarita/Documents/apache-airflow-project/dags/taxi_metrics_dag.py
[2024-03-18T11:39:02.424+0545] {processor.py:830} INFO - Processing file //home/sarita/Documents/apache-airflow-project/dags/taxi_metrics_dag.py for tasks to queue
[2024-03-18T11:39:02.427+0545] {logging_mixin.py:188} INFO - [2024-03-18T11:39:02.426+0545] {dagbag.py:540} INFO - Filling up the DagBag from //home/sarita/Documents/apache-airflow-project/dags/taxi_metrics_dag.py
[2024-03-18T11:39:02.436+0545] {logging_mixin.py:188} INFO - [2024-03-18T11:39:02.433+0545] {dagbag.py:350} ERROR - Failed to import: //home/sarita/Documents/apache-airflow-project/dags/taxi_metrics_dag.py
Traceback (most recent call last):
  File "/home/sarita/Documents/ETLapp/pythonProject/.venv/lib/python3.9/site-packages/airflow/models/dagbag.py", line 346, in parse
    loader.exec_module(new_module)
  File "<frozen importlib._bootstrap_external>", line 855, in exec_module
  File "<frozen importlib._bootstrap>", line 228, in _call_with_frames_removed
  File "//home/sarita/Documents/apache-airflow-project/dags/taxi_metrics_dag.py", line 11, in <module>
    from db_connection import BATCH_SIZE, get_sqlite_connection, get_clickhouse_connection, SQLITE_TABLE
ModuleNotFoundError: No module named 'db_connection'
[2024-03-18T11:39:02.437+0545] {processor.py:842} WARNING - No viable dags retrieved from //home/sarita/Documents/apache-airflow-project/dags/taxi_metrics_dag.py
[2024-03-18T11:39:02.460+0545] {processor.py:183} INFO - Processing //home/sarita/Documents/apache-airflow-project/dags/taxi_metrics_dag.py took 0.047 seconds
[2024-03-18T11:39:56.308+0545] {processor.py:161} INFO - Started process (PID=15775) to work on //home/sarita/Documents/apache-airflow-project/dags/taxi_metrics_dag.py
[2024-03-18T11:39:56.312+0545] {processor.py:830} INFO - Processing file //home/sarita/Documents/apache-airflow-project/dags/taxi_metrics_dag.py for tasks to queue
[2024-03-18T11:39:56.315+0545] {logging_mixin.py:188} INFO - [2024-03-18T11:39:56.313+0545] {dagbag.py:540} INFO - Filling up the DagBag from //home/sarita/Documents/apache-airflow-project/dags/taxi_metrics_dag.py
[2024-03-18T11:39:56.324+0545] {logging_mixin.py:188} INFO - [2024-03-18T11:39:56.322+0545] {dagbag.py:350} ERROR - Failed to import: //home/sarita/Documents/apache-airflow-project/dags/taxi_metrics_dag.py
Traceback (most recent call last):
  File "/home/sarita/Documents/ETLapp/pythonProject/.venv/lib/python3.9/site-packages/airflow/models/dagbag.py", line 346, in parse
    loader.exec_module(new_module)
  File "<frozen importlib._bootstrap_external>", line 855, in exec_module
  File "<frozen importlib._bootstrap>", line 228, in _call_with_frames_removed
  File "//home/sarita/Documents/apache-airflow-project/dags/taxi_metrics_dag.py", line 11, in <module>
    from db_connection import BATCH_SIZE, get_sqlite_connection, get_clickhouse_connection, SQLITE_TABLE
ModuleNotFoundError: No module named 'db_connection'
[2024-03-18T11:39:56.325+0545] {processor.py:842} WARNING - No viable dags retrieved from //home/sarita/Documents/apache-airflow-project/dags/taxi_metrics_dag.py
[2024-03-18T11:39:56.346+0545] {processor.py:183} INFO - Processing //home/sarita/Documents/apache-airflow-project/dags/taxi_metrics_dag.py took 0.047 seconds
[2024-03-18T11:40:51.346+0545] {processor.py:161} INFO - Started process (PID=15853) to work on //home/sarita/Documents/apache-airflow-project/dags/taxi_metrics_dag.py
[2024-03-18T11:40:51.349+0545] {processor.py:830} INFO - Processing file //home/sarita/Documents/apache-airflow-project/dags/taxi_metrics_dag.py for tasks to queue
[2024-03-18T11:40:51.350+0545] {logging_mixin.py:188} INFO - [2024-03-18T11:40:51.350+0545] {dagbag.py:540} INFO - Filling up the DagBag from //home/sarita/Documents/apache-airflow-project/dags/taxi_metrics_dag.py
[2024-03-18T11:40:51.355+0545] {logging_mixin.py:188} INFO - [2024-03-18T11:40:51.354+0545] {dagbag.py:350} ERROR - Failed to import: //home/sarita/Documents/apache-airflow-project/dags/taxi_metrics_dag.py
Traceback (most recent call last):
  File "/home/sarita/Documents/ETLapp/pythonProject/.venv/lib/python3.9/site-packages/airflow/models/dagbag.py", line 346, in parse
    loader.exec_module(new_module)
  File "<frozen importlib._bootstrap_external>", line 855, in exec_module
  File "<frozen importlib._bootstrap>", line 228, in _call_with_frames_removed
  File "//home/sarita/Documents/apache-airflow-project/dags/taxi_metrics_dag.py", line 11, in <module>
    from db_connection import BATCH_SIZE, get_sqlite_connection, get_clickhouse_connection, SQLITE_TABLE
ModuleNotFoundError: No module named 'db_connection'
[2024-03-18T11:40:51.356+0545] {processor.py:842} WARNING - No viable dags retrieved from //home/sarita/Documents/apache-airflow-project/dags/taxi_metrics_dag.py
[2024-03-18T11:40:51.377+0545] {processor.py:183} INFO - Processing //home/sarita/Documents/apache-airflow-project/dags/taxi_metrics_dag.py took 0.034 seconds
[2024-03-18T11:41:47.532+0545] {processor.py:161} INFO - Started process (PID=15946) to work on //home/sarita/Documents/apache-airflow-project/dags/taxi_metrics_dag.py
[2024-03-18T11:41:47.534+0545] {processor.py:830} INFO - Processing file //home/sarita/Documents/apache-airflow-project/dags/taxi_metrics_dag.py for tasks to queue
[2024-03-18T11:41:47.535+0545] {logging_mixin.py:188} INFO - [2024-03-18T11:41:47.535+0545] {dagbag.py:540} INFO - Filling up the DagBag from //home/sarita/Documents/apache-airflow-project/dags/taxi_metrics_dag.py
[2024-03-18T11:41:47.539+0545] {logging_mixin.py:188} INFO - [2024-03-18T11:41:47.538+0545] {dagbag.py:350} ERROR - Failed to import: //home/sarita/Documents/apache-airflow-project/dags/taxi_metrics_dag.py
Traceback (most recent call last):
  File "/home/sarita/Documents/ETLapp/pythonProject/.venv/lib/python3.9/site-packages/airflow/models/dagbag.py", line 346, in parse
    loader.exec_module(new_module)
  File "<frozen importlib._bootstrap_external>", line 855, in exec_module
  File "<frozen importlib._bootstrap>", line 228, in _call_with_frames_removed
  File "//home/sarita/Documents/apache-airflow-project/dags/taxi_metrics_dag.py", line 11, in <module>
    from db_connection import BATCH_SIZE, get_sqlite_connection, get_clickhouse_connection, SQLITE_TABLE
ModuleNotFoundError: No module named 'db_connection'
[2024-03-18T11:41:47.540+0545] {processor.py:842} WARNING - No viable dags retrieved from //home/sarita/Documents/apache-airflow-project/dags/taxi_metrics_dag.py
[2024-03-18T11:41:47.557+0545] {processor.py:183} INFO - Processing //home/sarita/Documents/apache-airflow-project/dags/taxi_metrics_dag.py took 0.029 seconds
[2024-03-18T11:42:45.236+0545] {processor.py:161} INFO - Started process (PID=16015) to work on //home/sarita/Documents/apache-airflow-project/dags/taxi_metrics_dag.py
[2024-03-18T11:42:45.239+0545] {processor.py:830} INFO - Processing file //home/sarita/Documents/apache-airflow-project/dags/taxi_metrics_dag.py for tasks to queue
[2024-03-18T11:42:45.240+0545] {logging_mixin.py:188} INFO - [2024-03-18T11:42:45.239+0545] {dagbag.py:540} INFO - Filling up the DagBag from //home/sarita/Documents/apache-airflow-project/dags/taxi_metrics_dag.py
[2024-03-18T11:42:45.245+0545] {logging_mixin.py:188} INFO - [2024-03-18T11:42:45.244+0545] {dagbag.py:350} ERROR - Failed to import: //home/sarita/Documents/apache-airflow-project/dags/taxi_metrics_dag.py
Traceback (most recent call last):
  File "/home/sarita/Documents/ETLapp/pythonProject/.venv/lib/python3.9/site-packages/airflow/models/dagbag.py", line 346, in parse
    loader.exec_module(new_module)
  File "<frozen importlib._bootstrap_external>", line 855, in exec_module
  File "<frozen importlib._bootstrap>", line 228, in _call_with_frames_removed
  File "//home/sarita/Documents/apache-airflow-project/dags/taxi_metrics_dag.py", line 11, in <module>
    from db_connection import BATCH_SIZE, get_sqlite_connection, get_clickhouse_connection, SQLITE_TABLE
ModuleNotFoundError: No module named 'db_connection'
[2024-03-18T11:42:45.245+0545] {processor.py:842} WARNING - No viable dags retrieved from //home/sarita/Documents/apache-airflow-project/dags/taxi_metrics_dag.py
[2024-03-18T11:42:45.266+0545] {processor.py:183} INFO - Processing //home/sarita/Documents/apache-airflow-project/dags/taxi_metrics_dag.py took 0.033 seconds
[2024-03-18T11:43:44.218+0545] {processor.py:161} INFO - Started process (PID=16093) to work on //home/sarita/Documents/apache-airflow-project/dags/taxi_metrics_dag.py
[2024-03-18T11:43:44.221+0545] {processor.py:830} INFO - Processing file //home/sarita/Documents/apache-airflow-project/dags/taxi_metrics_dag.py for tasks to queue
[2024-03-18T11:43:44.222+0545] {logging_mixin.py:188} INFO - [2024-03-18T11:43:44.222+0545] {dagbag.py:540} INFO - Filling up the DagBag from //home/sarita/Documents/apache-airflow-project/dags/taxi_metrics_dag.py
[2024-03-18T11:43:44.225+0545] {logging_mixin.py:188} INFO - [2024-03-18T11:43:44.224+0545] {dagbag.py:350} ERROR - Failed to import: //home/sarita/Documents/apache-airflow-project/dags/taxi_metrics_dag.py
Traceback (most recent call last):
  File "/home/sarita/Documents/ETLapp/pythonProject/.venv/lib/python3.9/site-packages/airflow/models/dagbag.py", line 346, in parse
    loader.exec_module(new_module)
  File "<frozen importlib._bootstrap_external>", line 855, in exec_module
  File "<frozen importlib._bootstrap>", line 228, in _call_with_frames_removed
  File "//home/sarita/Documents/apache-airflow-project/dags/taxi_metrics_dag.py", line 11, in <module>
    from db_connection import BATCH_SIZE, get_sqlite_connection, get_clickhouse_connection, SQLITE_TABLE
ModuleNotFoundError: No module named 'db_connection'
[2024-03-18T11:43:44.225+0545] {processor.py:842} WARNING - No viable dags retrieved from //home/sarita/Documents/apache-airflow-project/dags/taxi_metrics_dag.py
[2024-03-18T11:43:44.240+0545] {processor.py:183} INFO - Processing //home/sarita/Documents/apache-airflow-project/dags/taxi_metrics_dag.py took 0.025 seconds
[2024-03-18T11:44:40.879+0545] {processor.py:161} INFO - Started process (PID=16172) to work on //home/sarita/Documents/apache-airflow-project/dags/taxi_metrics_dag.py
[2024-03-18T11:44:40.881+0545] {processor.py:830} INFO - Processing file //home/sarita/Documents/apache-airflow-project/dags/taxi_metrics_dag.py for tasks to queue
[2024-03-18T11:44:40.882+0545] {logging_mixin.py:188} INFO - [2024-03-18T11:44:40.881+0545] {dagbag.py:540} INFO - Filling up the DagBag from //home/sarita/Documents/apache-airflow-project/dags/taxi_metrics_dag.py
[2024-03-18T11:44:40.884+0545] {logging_mixin.py:188} INFO - [2024-03-18T11:44:40.884+0545] {dagbag.py:350} ERROR - Failed to import: //home/sarita/Documents/apache-airflow-project/dags/taxi_metrics_dag.py
Traceback (most recent call last):
  File "/home/sarita/Documents/ETLapp/pythonProject/.venv/lib/python3.9/site-packages/airflow/models/dagbag.py", line 346, in parse
    loader.exec_module(new_module)
  File "<frozen importlib._bootstrap_external>", line 855, in exec_module
  File "<frozen importlib._bootstrap>", line 228, in _call_with_frames_removed
  File "//home/sarita/Documents/apache-airflow-project/dags/taxi_metrics_dag.py", line 11, in <module>
    from db_connection import BATCH_SIZE, get_sqlite_connection, get_clickhouse_connection, SQLITE_TABLE
ModuleNotFoundError: No module named 'db_connection'
[2024-03-18T11:44:40.885+0545] {processor.py:842} WARNING - No viable dags retrieved from //home/sarita/Documents/apache-airflow-project/dags/taxi_metrics_dag.py
[2024-03-18T11:44:40.899+0545] {processor.py:183} INFO - Processing //home/sarita/Documents/apache-airflow-project/dags/taxi_metrics_dag.py took 0.024 seconds
[2024-03-18T11:45:39.044+0545] {processor.py:161} INFO - Started process (PID=16249) to work on //home/sarita/Documents/apache-airflow-project/dags/taxi_metrics_dag.py
[2024-03-18T11:45:39.046+0545] {processor.py:830} INFO - Processing file //home/sarita/Documents/apache-airflow-project/dags/taxi_metrics_dag.py for tasks to queue
[2024-03-18T11:45:39.046+0545] {logging_mixin.py:188} INFO - [2024-03-18T11:45:39.046+0545] {dagbag.py:540} INFO - Filling up the DagBag from //home/sarita/Documents/apache-airflow-project/dags/taxi_metrics_dag.py
[2024-03-18T11:45:39.049+0545] {logging_mixin.py:188} INFO - [2024-03-18T11:45:39.048+0545] {dagbag.py:350} ERROR - Failed to import: //home/sarita/Documents/apache-airflow-project/dags/taxi_metrics_dag.py
Traceback (most recent call last):
  File "/home/sarita/Documents/ETLapp/pythonProject/.venv/lib/python3.9/site-packages/airflow/models/dagbag.py", line 346, in parse
    loader.exec_module(new_module)
  File "<frozen importlib._bootstrap_external>", line 855, in exec_module
  File "<frozen importlib._bootstrap>", line 228, in _call_with_frames_removed
  File "//home/sarita/Documents/apache-airflow-project/dags/taxi_metrics_dag.py", line 11, in <module>
    from db_connection import BATCH_SIZE, get_sqlite_connection, get_clickhouse_connection, SQLITE_TABLE
ModuleNotFoundError: No module named 'db_connection'
[2024-03-18T11:45:39.049+0545] {processor.py:842} WARNING - No viable dags retrieved from //home/sarita/Documents/apache-airflow-project/dags/taxi_metrics_dag.py
[2024-03-18T11:45:39.065+0545] {processor.py:183} INFO - Processing //home/sarita/Documents/apache-airflow-project/dags/taxi_metrics_dag.py took 0.024 seconds
[2024-03-18T11:46:36.534+0545] {processor.py:161} INFO - Started process (PID=16358) to work on //home/sarita/Documents/apache-airflow-project/dags/taxi_metrics_dag.py
[2024-03-18T11:46:36.536+0545] {processor.py:830} INFO - Processing file //home/sarita/Documents/apache-airflow-project/dags/taxi_metrics_dag.py for tasks to queue
[2024-03-18T11:46:36.537+0545] {logging_mixin.py:188} INFO - [2024-03-18T11:46:36.536+0545] {dagbag.py:540} INFO - Filling up the DagBag from //home/sarita/Documents/apache-airflow-project/dags/taxi_metrics_dag.py
[2024-03-18T11:46:36.539+0545] {logging_mixin.py:188} INFO - [2024-03-18T11:46:36.539+0545] {dagbag.py:350} ERROR - Failed to import: //home/sarita/Documents/apache-airflow-project/dags/taxi_metrics_dag.py
Traceback (most recent call last):
  File "/home/sarita/Documents/ETLapp/pythonProject/.venv/lib/python3.9/site-packages/airflow/models/dagbag.py", line 346, in parse
    loader.exec_module(new_module)
  File "<frozen importlib._bootstrap_external>", line 855, in exec_module
  File "<frozen importlib._bootstrap>", line 228, in _call_with_frames_removed
  File "//home/sarita/Documents/apache-airflow-project/dags/taxi_metrics_dag.py", line 11, in <module>
    from db_connection import BATCH_SIZE, get_sqlite_connection, get_clickhouse_connection, SQLITE_TABLE
ModuleNotFoundError: No module named 'db_connection'
[2024-03-18T11:46:36.539+0545] {processor.py:842} WARNING - No viable dags retrieved from //home/sarita/Documents/apache-airflow-project/dags/taxi_metrics_dag.py
[2024-03-18T11:46:36.555+0545] {processor.py:183} INFO - Processing //home/sarita/Documents/apache-airflow-project/dags/taxi_metrics_dag.py took 0.023 seconds
[2024-03-18T11:47:32.678+0545] {processor.py:161} INFO - Started process (PID=16458) to work on //home/sarita/Documents/apache-airflow-project/dags/taxi_metrics_dag.py
[2024-03-18T11:47:32.683+0545] {processor.py:830} INFO - Processing file //home/sarita/Documents/apache-airflow-project/dags/taxi_metrics_dag.py for tasks to queue
[2024-03-18T11:47:32.685+0545] {logging_mixin.py:188} INFO - [2024-03-18T11:47:32.684+0545] {dagbag.py:540} INFO - Filling up the DagBag from //home/sarita/Documents/apache-airflow-project/dags/taxi_metrics_dag.py
[2024-03-18T11:47:32.694+0545] {logging_mixin.py:188} INFO - [2024-03-18T11:47:32.693+0545] {dagbag.py:350} ERROR - Failed to import: //home/sarita/Documents/apache-airflow-project/dags/taxi_metrics_dag.py
Traceback (most recent call last):
  File "/home/sarita/Documents/ETLapp/pythonProject/.venv/lib/python3.9/site-packages/airflow/models/dagbag.py", line 346, in parse
    loader.exec_module(new_module)
  File "<frozen importlib._bootstrap_external>", line 855, in exec_module
  File "<frozen importlib._bootstrap>", line 228, in _call_with_frames_removed
  File "//home/sarita/Documents/apache-airflow-project/dags/taxi_metrics_dag.py", line 11, in <module>
    from db_connection import BATCH_SIZE, get_sqlite_connection, get_clickhouse_connection, SQLITE_TABLE
ModuleNotFoundError: No module named 'db_connection'
[2024-03-18T11:47:32.695+0545] {processor.py:842} WARNING - No viable dags retrieved from //home/sarita/Documents/apache-airflow-project/dags/taxi_metrics_dag.py
[2024-03-18T11:47:32.720+0545] {processor.py:183} INFO - Processing //home/sarita/Documents/apache-airflow-project/dags/taxi_metrics_dag.py took 0.050 seconds
[2024-03-18T11:48:27.843+0545] {processor.py:161} INFO - Started process (PID=16590) to work on //home/sarita/Documents/apache-airflow-project/dags/taxi_metrics_dag.py
[2024-03-18T11:48:27.845+0545] {processor.py:830} INFO - Processing file //home/sarita/Documents/apache-airflow-project/dags/taxi_metrics_dag.py for tasks to queue
[2024-03-18T11:48:27.846+0545] {logging_mixin.py:188} INFO - [2024-03-18T11:48:27.846+0545] {dagbag.py:540} INFO - Filling up the DagBag from //home/sarita/Documents/apache-airflow-project/dags/taxi_metrics_dag.py
[2024-03-18T11:48:27.849+0545] {logging_mixin.py:188} INFO - [2024-03-18T11:48:27.848+0545] {dagbag.py:350} ERROR - Failed to import: //home/sarita/Documents/apache-airflow-project/dags/taxi_metrics_dag.py
Traceback (most recent call last):
  File "/home/sarita/Documents/ETLapp/pythonProject/.venv/lib/python3.9/site-packages/airflow/models/dagbag.py", line 346, in parse
    loader.exec_module(new_module)
  File "<frozen importlib._bootstrap_external>", line 855, in exec_module
  File "<frozen importlib._bootstrap>", line 228, in _call_with_frames_removed
  File "//home/sarita/Documents/apache-airflow-project/dags/taxi_metrics_dag.py", line 11, in <module>
    from db_connection import BATCH_SIZE, get_sqlite_connection, get_clickhouse_connection, SQLITE_TABLE
ModuleNotFoundError: No module named 'db_connection'
[2024-03-18T11:48:27.850+0545] {processor.py:842} WARNING - No viable dags retrieved from //home/sarita/Documents/apache-airflow-project/dags/taxi_metrics_dag.py
[2024-03-18T11:48:27.866+0545] {processor.py:183} INFO - Processing //home/sarita/Documents/apache-airflow-project/dags/taxi_metrics_dag.py took 0.026 seconds
[2024-03-18T11:49:25.161+0545] {processor.py:161} INFO - Started process (PID=16678) to work on //home/sarita/Documents/apache-airflow-project/dags/taxi_metrics_dag.py
[2024-03-18T11:49:25.166+0545] {processor.py:830} INFO - Processing file //home/sarita/Documents/apache-airflow-project/dags/taxi_metrics_dag.py for tasks to queue
[2024-03-18T11:49:25.169+0545] {logging_mixin.py:188} INFO - [2024-03-18T11:49:25.168+0545] {dagbag.py:540} INFO - Filling up the DagBag from //home/sarita/Documents/apache-airflow-project/dags/taxi_metrics_dag.py
[2024-03-18T11:49:25.180+0545] {logging_mixin.py:188} INFO - [2024-03-18T11:49:25.178+0545] {dagbag.py:350} ERROR - Failed to import: //home/sarita/Documents/apache-airflow-project/dags/taxi_metrics_dag.py
Traceback (most recent call last):
  File "/home/sarita/Documents/ETLapp/pythonProject/.venv/lib/python3.9/site-packages/airflow/models/dagbag.py", line 346, in parse
    loader.exec_module(new_module)
  File "<frozen importlib._bootstrap_external>", line 855, in exec_module
  File "<frozen importlib._bootstrap>", line 228, in _call_with_frames_removed
  File "//home/sarita/Documents/apache-airflow-project/dags/taxi_metrics_dag.py", line 11, in <module>
    from db_connection import BATCH_SIZE, get_sqlite_connection, get_clickhouse_connection, SQLITE_TABLE
ModuleNotFoundError: No module named 'db_connection'
[2024-03-18T11:49:25.181+0545] {processor.py:842} WARNING - No viable dags retrieved from //home/sarita/Documents/apache-airflow-project/dags/taxi_metrics_dag.py
[2024-03-18T11:49:25.203+0545] {processor.py:183} INFO - Processing //home/sarita/Documents/apache-airflow-project/dags/taxi_metrics_dag.py took 0.052 seconds
[2024-03-18T11:50:19.874+0545] {processor.py:161} INFO - Started process (PID=16737) to work on //home/sarita/Documents/apache-airflow-project/dags/taxi_metrics_dag.py
[2024-03-18T11:50:19.877+0545] {processor.py:830} INFO - Processing file //home/sarita/Documents/apache-airflow-project/dags/taxi_metrics_dag.py for tasks to queue
[2024-03-18T11:50:19.878+0545] {logging_mixin.py:188} INFO - [2024-03-18T11:50:19.877+0545] {dagbag.py:540} INFO - Filling up the DagBag from //home/sarita/Documents/apache-airflow-project/dags/taxi_metrics_dag.py
[2024-03-18T11:50:19.881+0545] {logging_mixin.py:188} INFO - [2024-03-18T11:50:19.881+0545] {dagbag.py:350} ERROR - Failed to import: //home/sarita/Documents/apache-airflow-project/dags/taxi_metrics_dag.py
Traceback (most recent call last):
  File "/home/sarita/Documents/ETLapp/pythonProject/.venv/lib/python3.9/site-packages/airflow/models/dagbag.py", line 346, in parse
    loader.exec_module(new_module)
  File "<frozen importlib._bootstrap_external>", line 855, in exec_module
  File "<frozen importlib._bootstrap>", line 228, in _call_with_frames_removed
  File "//home/sarita/Documents/apache-airflow-project/dags/taxi_metrics_dag.py", line 11, in <module>
    from db_connection import BATCH_SIZE, get_sqlite_connection, get_clickhouse_connection, SQLITE_TABLE
ModuleNotFoundError: No module named 'db_connection'
[2024-03-18T11:50:19.882+0545] {processor.py:842} WARNING - No viable dags retrieved from //home/sarita/Documents/apache-airflow-project/dags/taxi_metrics_dag.py
[2024-03-18T11:50:19.901+0545] {processor.py:183} INFO - Processing //home/sarita/Documents/apache-airflow-project/dags/taxi_metrics_dag.py took 0.029 seconds
[2024-03-18T11:51:19.225+0545] {processor.py:161} INFO - Started process (PID=16898) to work on //home/sarita/Documents/apache-airflow-project/dags/taxi_metrics_dag.py
[2024-03-18T11:51:19.227+0545] {processor.py:830} INFO - Processing file //home/sarita/Documents/apache-airflow-project/dags/taxi_metrics_dag.py for tasks to queue
[2024-03-18T11:51:19.228+0545] {logging_mixin.py:188} INFO - [2024-03-18T11:51:19.228+0545] {dagbag.py:540} INFO - Filling up the DagBag from //home/sarita/Documents/apache-airflow-project/dags/taxi_metrics_dag.py
[2024-03-18T11:51:19.230+0545] {logging_mixin.py:188} INFO - [2024-03-18T11:51:19.230+0545] {dagbag.py:350} ERROR - Failed to import: //home/sarita/Documents/apache-airflow-project/dags/taxi_metrics_dag.py
Traceback (most recent call last):
  File "/home/sarita/Documents/ETLapp/pythonProject/.venv/lib/python3.9/site-packages/airflow/models/dagbag.py", line 346, in parse
    loader.exec_module(new_module)
  File "<frozen importlib._bootstrap_external>", line 855, in exec_module
  File "<frozen importlib._bootstrap>", line 228, in _call_with_frames_removed
  File "//home/sarita/Documents/apache-airflow-project/dags/taxi_metrics_dag.py", line 11, in <module>
    from db_connection import BATCH_SIZE, get_sqlite_connection, get_clickhouse_connection, SQLITE_TABLE
ModuleNotFoundError: No module named 'db_connection'
[2024-03-18T11:51:19.231+0545] {processor.py:842} WARNING - No viable dags retrieved from //home/sarita/Documents/apache-airflow-project/dags/taxi_metrics_dag.py
[2024-03-18T11:51:19.244+0545] {processor.py:183} INFO - Processing //home/sarita/Documents/apache-airflow-project/dags/taxi_metrics_dag.py took 0.020 seconds
[2024-03-18T11:52:20.455+0545] {processor.py:161} INFO - Started process (PID=17039) to work on //home/sarita/Documents/apache-airflow-project/dags/taxi_metrics_dag.py
[2024-03-18T11:52:20.457+0545] {processor.py:830} INFO - Processing file //home/sarita/Documents/apache-airflow-project/dags/taxi_metrics_dag.py for tasks to queue
[2024-03-18T11:52:20.457+0545] {logging_mixin.py:188} INFO - [2024-03-18T11:52:20.457+0545] {dagbag.py:540} INFO - Filling up the DagBag from //home/sarita/Documents/apache-airflow-project/dags/taxi_metrics_dag.py
[2024-03-18T11:52:20.460+0545] {logging_mixin.py:188} INFO - [2024-03-18T11:52:20.459+0545] {dagbag.py:350} ERROR - Failed to import: //home/sarita/Documents/apache-airflow-project/dags/taxi_metrics_dag.py
Traceback (most recent call last):
  File "/home/sarita/Documents/ETLapp/pythonProject/.venv/lib/python3.9/site-packages/airflow/models/dagbag.py", line 346, in parse
    loader.exec_module(new_module)
  File "<frozen importlib._bootstrap_external>", line 855, in exec_module
  File "<frozen importlib._bootstrap>", line 228, in _call_with_frames_removed
  File "//home/sarita/Documents/apache-airflow-project/dags/taxi_metrics_dag.py", line 11, in <module>
    from db_connection import BATCH_SIZE, get_sqlite_connection, get_clickhouse_connection, SQLITE_TABLE
ModuleNotFoundError: No module named 'db_connection'
[2024-03-18T11:52:20.460+0545] {processor.py:842} WARNING - No viable dags retrieved from //home/sarita/Documents/apache-airflow-project/dags/taxi_metrics_dag.py
[2024-03-18T11:52:20.475+0545] {processor.py:183} INFO - Processing //home/sarita/Documents/apache-airflow-project/dags/taxi_metrics_dag.py took 0.022 seconds
[2024-03-18T11:53:21.982+0545] {processor.py:161} INFO - Started process (PID=17220) to work on //home/sarita/Documents/apache-airflow-project/dags/taxi_metrics_dag.py
[2024-03-18T11:53:21.985+0545] {processor.py:830} INFO - Processing file //home/sarita/Documents/apache-airflow-project/dags/taxi_metrics_dag.py for tasks to queue
[2024-03-18T11:53:21.988+0545] {logging_mixin.py:188} INFO - [2024-03-18T11:53:21.987+0545] {dagbag.py:540} INFO - Filling up the DagBag from //home/sarita/Documents/apache-airflow-project/dags/taxi_metrics_dag.py
[2024-03-18T11:53:21.998+0545] {logging_mixin.py:188} INFO - [2024-03-18T11:53:21.996+0545] {dagbag.py:350} ERROR - Failed to import: //home/sarita/Documents/apache-airflow-project/dags/taxi_metrics_dag.py
Traceback (most recent call last):
  File "/home/sarita/Documents/ETLapp/pythonProject/.venv/lib/python3.9/site-packages/airflow/models/dagbag.py", line 346, in parse
    loader.exec_module(new_module)
  File "<frozen importlib._bootstrap_external>", line 855, in exec_module
  File "<frozen importlib._bootstrap>", line 228, in _call_with_frames_removed
  File "//home/sarita/Documents/apache-airflow-project/dags/taxi_metrics_dag.py", line 11, in <module>
    from db_connection import BATCH_SIZE, get_sqlite_connection, get_clickhouse_connection, SQLITE_TABLE
ModuleNotFoundError: No module named 'db_connection'
[2024-03-18T11:53:21.999+0545] {processor.py:842} WARNING - No viable dags retrieved from //home/sarita/Documents/apache-airflow-project/dags/taxi_metrics_dag.py
[2024-03-18T11:53:22.021+0545] {processor.py:183} INFO - Processing //home/sarita/Documents/apache-airflow-project/dags/taxi_metrics_dag.py took 0.047 seconds
[2024-03-18T11:54:17.971+0545] {processor.py:161} INFO - Started process (PID=17361) to work on //home/sarita/Documents/apache-airflow-project/dags/taxi_metrics_dag.py
[2024-03-18T11:54:17.974+0545] {processor.py:830} INFO - Processing file //home/sarita/Documents/apache-airflow-project/dags/taxi_metrics_dag.py for tasks to queue
[2024-03-18T11:54:17.977+0545] {logging_mixin.py:188} INFO - [2024-03-18T11:54:17.976+0545] {dagbag.py:540} INFO - Filling up the DagBag from //home/sarita/Documents/apache-airflow-project/dags/taxi_metrics_dag.py
[2024-03-18T11:54:17.986+0545] {logging_mixin.py:188} INFO - [2024-03-18T11:54:17.984+0545] {dagbag.py:350} ERROR - Failed to import: //home/sarita/Documents/apache-airflow-project/dags/taxi_metrics_dag.py
Traceback (most recent call last):
  File "/home/sarita/Documents/ETLapp/pythonProject/.venv/lib/python3.9/site-packages/airflow/models/dagbag.py", line 346, in parse
    loader.exec_module(new_module)
  File "<frozen importlib._bootstrap_external>", line 855, in exec_module
  File "<frozen importlib._bootstrap>", line 228, in _call_with_frames_removed
  File "//home/sarita/Documents/apache-airflow-project/dags/taxi_metrics_dag.py", line 11, in <module>
    from db_connection import BATCH_SIZE, get_sqlite_connection, get_clickhouse_connection, SQLITE_TABLE
ModuleNotFoundError: No module named 'db_connection'
[2024-03-18T11:54:17.987+0545] {processor.py:842} WARNING - No viable dags retrieved from //home/sarita/Documents/apache-airflow-project/dags/taxi_metrics_dag.py
[2024-03-18T11:54:18.009+0545] {processor.py:183} INFO - Processing //home/sarita/Documents/apache-airflow-project/dags/taxi_metrics_dag.py took 0.046 seconds
[2024-03-18T11:55:15.391+0545] {processor.py:161} INFO - Started process (PID=17435) to work on //home/sarita/Documents/apache-airflow-project/dags/taxi_metrics_dag.py
[2024-03-18T11:55:15.394+0545] {processor.py:830} INFO - Processing file //home/sarita/Documents/apache-airflow-project/dags/taxi_metrics_dag.py for tasks to queue
[2024-03-18T11:55:15.395+0545] {logging_mixin.py:188} INFO - [2024-03-18T11:55:15.394+0545] {dagbag.py:540} INFO - Filling up the DagBag from //home/sarita/Documents/apache-airflow-project/dags/taxi_metrics_dag.py
[2024-03-18T11:55:15.398+0545] {logging_mixin.py:188} INFO - [2024-03-18T11:55:15.397+0545] {dagbag.py:350} ERROR - Failed to import: //home/sarita/Documents/apache-airflow-project/dags/taxi_metrics_dag.py
Traceback (most recent call last):
  File "/home/sarita/Documents/ETLapp/pythonProject/.venv/lib/python3.9/site-packages/airflow/models/dagbag.py", line 346, in parse
    loader.exec_module(new_module)
  File "<frozen importlib._bootstrap_external>", line 855, in exec_module
  File "<frozen importlib._bootstrap>", line 228, in _call_with_frames_removed
  File "//home/sarita/Documents/apache-airflow-project/dags/taxi_metrics_dag.py", line 11, in <module>
    from db_connection import BATCH_SIZE, get_sqlite_connection, get_clickhouse_connection, SQLITE_TABLE
ModuleNotFoundError: No module named 'db_connection'
[2024-03-18T11:55:15.399+0545] {processor.py:842} WARNING - No viable dags retrieved from //home/sarita/Documents/apache-airflow-project/dags/taxi_metrics_dag.py
[2024-03-18T11:55:15.419+0545] {processor.py:183} INFO - Processing //home/sarita/Documents/apache-airflow-project/dags/taxi_metrics_dag.py took 0.030 seconds
[2024-03-18T11:56:16.174+0545] {processor.py:161} INFO - Started process (PID=17621) to work on //home/sarita/Documents/apache-airflow-project/dags/taxi_metrics_dag.py
[2024-03-18T11:56:16.178+0545] {processor.py:830} INFO - Processing file //home/sarita/Documents/apache-airflow-project/dags/taxi_metrics_dag.py for tasks to queue
[2024-03-18T11:56:16.181+0545] {logging_mixin.py:188} INFO - [2024-03-18T11:56:16.180+0545] {dagbag.py:540} INFO - Filling up the DagBag from //home/sarita/Documents/apache-airflow-project/dags/taxi_metrics_dag.py
[2024-03-18T11:56:16.191+0545] {logging_mixin.py:188} INFO - [2024-03-18T11:56:16.189+0545] {dagbag.py:350} ERROR - Failed to import: //home/sarita/Documents/apache-airflow-project/dags/taxi_metrics_dag.py
Traceback (most recent call last):
  File "/home/sarita/Documents/ETLapp/pythonProject/.venv/lib/python3.9/site-packages/airflow/models/dagbag.py", line 346, in parse
    loader.exec_module(new_module)
  File "<frozen importlib._bootstrap_external>", line 855, in exec_module
  File "<frozen importlib._bootstrap>", line 228, in _call_with_frames_removed
  File "//home/sarita/Documents/apache-airflow-project/dags/taxi_metrics_dag.py", line 11, in <module>
    from db_connection import BATCH_SIZE, get_sqlite_connection, get_clickhouse_connection, SQLITE_TABLE
ModuleNotFoundError: No module named 'db_connection'
[2024-03-18T11:56:16.192+0545] {processor.py:842} WARNING - No viable dags retrieved from //home/sarita/Documents/apache-airflow-project/dags/taxi_metrics_dag.py
[2024-03-18T11:56:16.212+0545] {processor.py:183} INFO - Processing //home/sarita/Documents/apache-airflow-project/dags/taxi_metrics_dag.py took 0.046 seconds
[2024-03-18T11:57:12.538+0545] {processor.py:161} INFO - Started process (PID=17728) to work on //home/sarita/Documents/apache-airflow-project/dags/taxi_metrics_dag.py
[2024-03-18T11:57:12.542+0545] {processor.py:830} INFO - Processing file //home/sarita/Documents/apache-airflow-project/dags/taxi_metrics_dag.py for tasks to queue
[2024-03-18T11:57:12.545+0545] {logging_mixin.py:188} INFO - [2024-03-18T11:57:12.544+0545] {dagbag.py:540} INFO - Filling up the DagBag from //home/sarita/Documents/apache-airflow-project/dags/taxi_metrics_dag.py
[2024-03-18T11:57:12.554+0545] {logging_mixin.py:188} INFO - [2024-03-18T11:57:12.552+0545] {dagbag.py:350} ERROR - Failed to import: //home/sarita/Documents/apache-airflow-project/dags/taxi_metrics_dag.py
Traceback (most recent call last):
  File "/home/sarita/Documents/ETLapp/pythonProject/.venv/lib/python3.9/site-packages/airflow/models/dagbag.py", line 346, in parse
    loader.exec_module(new_module)
  File "<frozen importlib._bootstrap_external>", line 855, in exec_module
  File "<frozen importlib._bootstrap>", line 228, in _call_with_frames_removed
  File "//home/sarita/Documents/apache-airflow-project/dags/taxi_metrics_dag.py", line 11, in <module>
    from db_connection import BATCH_SIZE, get_sqlite_connection, get_clickhouse_connection, SQLITE_TABLE
ModuleNotFoundError: No module named 'db_connection'
[2024-03-18T11:57:12.555+0545] {processor.py:842} WARNING - No viable dags retrieved from //home/sarita/Documents/apache-airflow-project/dags/taxi_metrics_dag.py
[2024-03-18T11:57:12.575+0545] {processor.py:183} INFO - Processing //home/sarita/Documents/apache-airflow-project/dags/taxi_metrics_dag.py took 0.044 seconds
[2024-03-18T11:58:05.268+0545] {processor.py:161} INFO - Started process (PID=17795) to work on //home/sarita/Documents/apache-airflow-project/dags/taxi_metrics_dag.py
[2024-03-18T11:58:05.272+0545] {processor.py:830} INFO - Processing file //home/sarita/Documents/apache-airflow-project/dags/taxi_metrics_dag.py for tasks to queue
[2024-03-18T11:58:05.275+0545] {logging_mixin.py:188} INFO - [2024-03-18T11:58:05.274+0545] {dagbag.py:540} INFO - Filling up the DagBag from //home/sarita/Documents/apache-airflow-project/dags/taxi_metrics_dag.py
[2024-03-18T11:58:05.285+0545] {logging_mixin.py:188} INFO - [2024-03-18T11:58:05.283+0545] {dagbag.py:350} ERROR - Failed to import: //home/sarita/Documents/apache-airflow-project/dags/taxi_metrics_dag.py
Traceback (most recent call last):
  File "/home/sarita/Documents/ETLapp/pythonProject/.venv/lib/python3.9/site-packages/airflow/models/dagbag.py", line 346, in parse
    loader.exec_module(new_module)
  File "<frozen importlib._bootstrap_external>", line 855, in exec_module
  File "<frozen importlib._bootstrap>", line 228, in _call_with_frames_removed
  File "//home/sarita/Documents/apache-airflow-project/dags/taxi_metrics_dag.py", line 11, in <module>
    from db_connection import BATCH_SIZE, get_sqlite_connection, get_clickhouse_connection, SQLITE_TABLE
ModuleNotFoundError: No module named 'db_connection'
[2024-03-18T11:58:05.286+0545] {processor.py:842} WARNING - No viable dags retrieved from //home/sarita/Documents/apache-airflow-project/dags/taxi_metrics_dag.py
[2024-03-18T11:58:05.307+0545] {processor.py:183} INFO - Processing //home/sarita/Documents/apache-airflow-project/dags/taxi_metrics_dag.py took 0.047 seconds
[2024-03-18T11:59:01.860+0545] {processor.py:161} INFO - Started process (PID=17867) to work on //home/sarita/Documents/apache-airflow-project/dags/taxi_metrics_dag.py
[2024-03-18T11:59:01.863+0545] {processor.py:830} INFO - Processing file //home/sarita/Documents/apache-airflow-project/dags/taxi_metrics_dag.py for tasks to queue
[2024-03-18T11:59:01.866+0545] {logging_mixin.py:188} INFO - [2024-03-18T11:59:01.865+0545] {dagbag.py:540} INFO - Filling up the DagBag from //home/sarita/Documents/apache-airflow-project/dags/taxi_metrics_dag.py
[2024-03-18T11:59:01.875+0545] {logging_mixin.py:188} INFO - [2024-03-18T11:59:01.873+0545] {dagbag.py:350} ERROR - Failed to import: //home/sarita/Documents/apache-airflow-project/dags/taxi_metrics_dag.py
Traceback (most recent call last):
  File "/home/sarita/Documents/ETLapp/pythonProject/.venv/lib/python3.9/site-packages/airflow/models/dagbag.py", line 346, in parse
    loader.exec_module(new_module)
  File "<frozen importlib._bootstrap_external>", line 855, in exec_module
  File "<frozen importlib._bootstrap>", line 228, in _call_with_frames_removed
  File "//home/sarita/Documents/apache-airflow-project/dags/taxi_metrics_dag.py", line 11, in <module>
    from db_connection import BATCH_SIZE, get_sqlite_connection, get_clickhouse_connection, SQLITE_TABLE
ModuleNotFoundError: No module named 'db_connection'
[2024-03-18T11:59:01.876+0545] {processor.py:842} WARNING - No viable dags retrieved from //home/sarita/Documents/apache-airflow-project/dags/taxi_metrics_dag.py
[2024-03-18T11:59:01.897+0545] {processor.py:183} INFO - Processing //home/sarita/Documents/apache-airflow-project/dags/taxi_metrics_dag.py took 0.045 seconds
[2024-03-18T11:59:56.411+0545] {processor.py:161} INFO - Started process (PID=17973) to work on //home/sarita/Documents/apache-airflow-project/dags/taxi_metrics_dag.py
[2024-03-18T11:59:56.415+0545] {processor.py:830} INFO - Processing file //home/sarita/Documents/apache-airflow-project/dags/taxi_metrics_dag.py for tasks to queue
[2024-03-18T11:59:56.418+0545] {logging_mixin.py:188} INFO - [2024-03-18T11:59:56.417+0545] {dagbag.py:540} INFO - Filling up the DagBag from //home/sarita/Documents/apache-airflow-project/dags/taxi_metrics_dag.py
[2024-03-18T11:59:56.426+0545] {logging_mixin.py:188} INFO - [2024-03-18T11:59:56.424+0545] {dagbag.py:350} ERROR - Failed to import: //home/sarita/Documents/apache-airflow-project/dags/taxi_metrics_dag.py
Traceback (most recent call last):
  File "/home/sarita/Documents/ETLapp/pythonProject/.venv/lib/python3.9/site-packages/airflow/models/dagbag.py", line 346, in parse
    loader.exec_module(new_module)
  File "<frozen importlib._bootstrap_external>", line 855, in exec_module
  File "<frozen importlib._bootstrap>", line 228, in _call_with_frames_removed
  File "//home/sarita/Documents/apache-airflow-project/dags/taxi_metrics_dag.py", line 11, in <module>
    from db_connection import BATCH_SIZE, get_sqlite_connection, get_clickhouse_connection, SQLITE_TABLE
ModuleNotFoundError: No module named 'db_connection'
[2024-03-18T11:59:56.427+0545] {processor.py:842} WARNING - No viable dags retrieved from //home/sarita/Documents/apache-airflow-project/dags/taxi_metrics_dag.py
[2024-03-18T11:59:56.447+0545] {processor.py:183} INFO - Processing //home/sarita/Documents/apache-airflow-project/dags/taxi_metrics_dag.py took 0.043 seconds
[2024-03-18T12:00:51.073+0545] {processor.py:161} INFO - Started process (PID=18046) to work on //home/sarita/Documents/apache-airflow-project/dags/taxi_metrics_dag.py
[2024-03-18T12:00:51.075+0545] {processor.py:830} INFO - Processing file //home/sarita/Documents/apache-airflow-project/dags/taxi_metrics_dag.py for tasks to queue
[2024-03-18T12:00:51.076+0545] {logging_mixin.py:188} INFO - [2024-03-18T12:00:51.076+0545] {dagbag.py:540} INFO - Filling up the DagBag from //home/sarita/Documents/apache-airflow-project/dags/taxi_metrics_dag.py
[2024-03-18T12:00:51.078+0545] {logging_mixin.py:188} INFO - [2024-03-18T12:00:51.078+0545] {dagbag.py:350} ERROR - Failed to import: //home/sarita/Documents/apache-airflow-project/dags/taxi_metrics_dag.py
Traceback (most recent call last):
  File "/home/sarita/Documents/ETLapp/pythonProject/.venv/lib/python3.9/site-packages/airflow/models/dagbag.py", line 346, in parse
    loader.exec_module(new_module)
  File "<frozen importlib._bootstrap_external>", line 855, in exec_module
  File "<frozen importlib._bootstrap>", line 228, in _call_with_frames_removed
  File "//home/sarita/Documents/apache-airflow-project/dags/taxi_metrics_dag.py", line 11, in <module>
    from db_connection import BATCH_SIZE, get_sqlite_connection, get_clickhouse_connection, SQLITE_TABLE
ModuleNotFoundError: No module named 'db_connection'
[2024-03-18T12:00:51.079+0545] {processor.py:842} WARNING - No viable dags retrieved from //home/sarita/Documents/apache-airflow-project/dags/taxi_metrics_dag.py
[2024-03-18T12:00:51.092+0545] {processor.py:183} INFO - Processing //home/sarita/Documents/apache-airflow-project/dags/taxi_metrics_dag.py took 0.021 seconds
[2024-03-18T12:01:49.631+0545] {processor.py:161} INFO - Started process (PID=18119) to work on //home/sarita/Documents/apache-airflow-project/dags/taxi_metrics_dag.py
[2024-03-18T12:01:49.635+0545] {processor.py:830} INFO - Processing file //home/sarita/Documents/apache-airflow-project/dags/taxi_metrics_dag.py for tasks to queue
[2024-03-18T12:01:49.637+0545] {logging_mixin.py:188} INFO - [2024-03-18T12:01:49.636+0545] {dagbag.py:540} INFO - Filling up the DagBag from //home/sarita/Documents/apache-airflow-project/dags/taxi_metrics_dag.py
[2024-03-18T12:01:49.647+0545] {logging_mixin.py:188} INFO - [2024-03-18T12:01:49.645+0545] {dagbag.py:350} ERROR - Failed to import: //home/sarita/Documents/apache-airflow-project/dags/taxi_metrics_dag.py
Traceback (most recent call last):
  File "/home/sarita/Documents/ETLapp/pythonProject/.venv/lib/python3.9/site-packages/airflow/models/dagbag.py", line 346, in parse
    loader.exec_module(new_module)
  File "<frozen importlib._bootstrap_external>", line 855, in exec_module
  File "<frozen importlib._bootstrap>", line 228, in _call_with_frames_removed
  File "//home/sarita/Documents/apache-airflow-project/dags/taxi_metrics_dag.py", line 11, in <module>
    from db_connection import BATCH_SIZE, get_sqlite_connection, get_clickhouse_connection, SQLITE_TABLE
ModuleNotFoundError: No module named 'db_connection'
[2024-03-18T12:01:49.648+0545] {processor.py:842} WARNING - No viable dags retrieved from //home/sarita/Documents/apache-airflow-project/dags/taxi_metrics_dag.py
[2024-03-18T12:01:49.670+0545] {processor.py:183} INFO - Processing //home/sarita/Documents/apache-airflow-project/dags/taxi_metrics_dag.py took 0.047 seconds
[2024-03-18T12:02:45.139+0545] {processor.py:161} INFO - Started process (PID=18195) to work on //home/sarita/Documents/apache-airflow-project/dags/taxi_metrics_dag.py
[2024-03-18T12:02:45.143+0545] {processor.py:830} INFO - Processing file //home/sarita/Documents/apache-airflow-project/dags/taxi_metrics_dag.py for tasks to queue
[2024-03-18T12:02:45.145+0545] {logging_mixin.py:188} INFO - [2024-03-18T12:02:45.144+0545] {dagbag.py:540} INFO - Filling up the DagBag from //home/sarita/Documents/apache-airflow-project/dags/taxi_metrics_dag.py
[2024-03-18T12:02:45.155+0545] {logging_mixin.py:188} INFO - [2024-03-18T12:02:45.152+0545] {dagbag.py:350} ERROR - Failed to import: //home/sarita/Documents/apache-airflow-project/dags/taxi_metrics_dag.py
Traceback (most recent call last):
  File "/home/sarita/Documents/ETLapp/pythonProject/.venv/lib/python3.9/site-packages/airflow/models/dagbag.py", line 346, in parse
    loader.exec_module(new_module)
  File "<frozen importlib._bootstrap_external>", line 855, in exec_module
  File "<frozen importlib._bootstrap>", line 228, in _call_with_frames_removed
  File "//home/sarita/Documents/apache-airflow-project/dags/taxi_metrics_dag.py", line 11, in <module>
    from db_connection import BATCH_SIZE, get_sqlite_connection, get_clickhouse_connection, SQLITE_TABLE
ModuleNotFoundError: No module named 'db_connection'
[2024-03-18T12:02:45.155+0545] {processor.py:842} WARNING - No viable dags retrieved from //home/sarita/Documents/apache-airflow-project/dags/taxi_metrics_dag.py
[2024-03-18T12:02:45.177+0545] {processor.py:183} INFO - Processing //home/sarita/Documents/apache-airflow-project/dags/taxi_metrics_dag.py took 0.045 seconds
[2024-03-18T12:03:41.593+0545] {processor.py:161} INFO - Started process (PID=18293) to work on //home/sarita/Documents/apache-airflow-project/dags/taxi_metrics_dag.py
[2024-03-18T12:03:41.596+0545] {processor.py:830} INFO - Processing file //home/sarita/Documents/apache-airflow-project/dags/taxi_metrics_dag.py for tasks to queue
[2024-03-18T12:03:41.596+0545] {logging_mixin.py:188} INFO - [2024-03-18T12:03:41.596+0545] {dagbag.py:540} INFO - Filling up the DagBag from //home/sarita/Documents/apache-airflow-project/dags/taxi_metrics_dag.py
[2024-03-18T12:03:41.600+0545] {logging_mixin.py:188} INFO - [2024-03-18T12:03:41.599+0545] {dagbag.py:350} ERROR - Failed to import: //home/sarita/Documents/apache-airflow-project/dags/taxi_metrics_dag.py
Traceback (most recent call last):
  File "/home/sarita/Documents/ETLapp/pythonProject/.venv/lib/python3.9/site-packages/airflow/models/dagbag.py", line 346, in parse
    loader.exec_module(new_module)
  File "<frozen importlib._bootstrap_external>", line 855, in exec_module
  File "<frozen importlib._bootstrap>", line 228, in _call_with_frames_removed
  File "//home/sarita/Documents/apache-airflow-project/dags/taxi_metrics_dag.py", line 11, in <module>
    from db_connection import BATCH_SIZE, get_sqlite_connection, get_clickhouse_connection, SQLITE_TABLE
ModuleNotFoundError: No module named 'db_connection'
[2024-03-18T12:03:41.600+0545] {processor.py:842} WARNING - No viable dags retrieved from //home/sarita/Documents/apache-airflow-project/dags/taxi_metrics_dag.py
[2024-03-18T12:03:41.620+0545] {processor.py:183} INFO - Processing //home/sarita/Documents/apache-airflow-project/dags/taxi_metrics_dag.py took 0.030 seconds
[2024-03-18T12:04:37.902+0545] {processor.py:161} INFO - Started process (PID=18359) to work on //home/sarita/Documents/apache-airflow-project/dags/taxi_metrics_dag.py
[2024-03-18T12:04:37.904+0545] {processor.py:830} INFO - Processing file //home/sarita/Documents/apache-airflow-project/dags/taxi_metrics_dag.py for tasks to queue
[2024-03-18T12:04:37.905+0545] {logging_mixin.py:188} INFO - [2024-03-18T12:04:37.905+0545] {dagbag.py:540} INFO - Filling up the DagBag from //home/sarita/Documents/apache-airflow-project/dags/taxi_metrics_dag.py
[2024-03-18T12:04:37.908+0545] {logging_mixin.py:188} INFO - [2024-03-18T12:04:37.907+0545] {dagbag.py:350} ERROR - Failed to import: //home/sarita/Documents/apache-airflow-project/dags/taxi_metrics_dag.py
Traceback (most recent call last):
  File "/home/sarita/Documents/ETLapp/pythonProject/.venv/lib/python3.9/site-packages/airflow/models/dagbag.py", line 346, in parse
    loader.exec_module(new_module)
  File "<frozen importlib._bootstrap_external>", line 855, in exec_module
  File "<frozen importlib._bootstrap>", line 228, in _call_with_frames_removed
  File "//home/sarita/Documents/apache-airflow-project/dags/taxi_metrics_dag.py", line 11, in <module>
    from db_connection import BATCH_SIZE, get_sqlite_connection, get_clickhouse_connection, SQLITE_TABLE
ModuleNotFoundError: No module named 'db_connection'
[2024-03-18T12:04:37.908+0545] {processor.py:842} WARNING - No viable dags retrieved from //home/sarita/Documents/apache-airflow-project/dags/taxi_metrics_dag.py
[2024-03-18T12:04:37.922+0545] {processor.py:183} INFO - Processing //home/sarita/Documents/apache-airflow-project/dags/taxi_metrics_dag.py took 0.022 seconds
[2024-03-18T12:05:31.210+0545] {processor.py:161} INFO - Started process (PID=18419) to work on //home/sarita/Documents/apache-airflow-project/dags/taxi_metrics_dag.py
[2024-03-18T12:05:31.212+0545] {processor.py:830} INFO - Processing file //home/sarita/Documents/apache-airflow-project/dags/taxi_metrics_dag.py for tasks to queue
[2024-03-18T12:05:31.213+0545] {logging_mixin.py:188} INFO - [2024-03-18T12:05:31.213+0545] {dagbag.py:540} INFO - Filling up the DagBag from //home/sarita/Documents/apache-airflow-project/dags/taxi_metrics_dag.py
[2024-03-18T12:05:31.215+0545] {logging_mixin.py:188} INFO - [2024-03-18T12:05:31.215+0545] {dagbag.py:350} ERROR - Failed to import: //home/sarita/Documents/apache-airflow-project/dags/taxi_metrics_dag.py
Traceback (most recent call last):
  File "/home/sarita/Documents/ETLapp/pythonProject/.venv/lib/python3.9/site-packages/airflow/models/dagbag.py", line 346, in parse
    loader.exec_module(new_module)
  File "<frozen importlib._bootstrap_external>", line 855, in exec_module
  File "<frozen importlib._bootstrap>", line 228, in _call_with_frames_removed
  File "//home/sarita/Documents/apache-airflow-project/dags/taxi_metrics_dag.py", line 11, in <module>
    from db_connection import BATCH_SIZE, get_sqlite_connection, get_clickhouse_connection, SQLITE_TABLE
ModuleNotFoundError: No module named 'db_connection'
[2024-03-18T12:05:31.216+0545] {processor.py:842} WARNING - No viable dags retrieved from //home/sarita/Documents/apache-airflow-project/dags/taxi_metrics_dag.py
[2024-03-18T12:05:31.229+0545] {processor.py:183} INFO - Processing //home/sarita/Documents/apache-airflow-project/dags/taxi_metrics_dag.py took 0.021 seconds
[2024-03-18T12:06:28.721+0545] {processor.py:161} INFO - Started process (PID=18484) to work on //home/sarita/Documents/apache-airflow-project/dags/taxi_metrics_dag.py
[2024-03-18T12:06:28.723+0545] {processor.py:830} INFO - Processing file //home/sarita/Documents/apache-airflow-project/dags/taxi_metrics_dag.py for tasks to queue
[2024-03-18T12:06:28.724+0545] {logging_mixin.py:188} INFO - [2024-03-18T12:06:28.723+0545] {dagbag.py:540} INFO - Filling up the DagBag from //home/sarita/Documents/apache-airflow-project/dags/taxi_metrics_dag.py
[2024-03-18T12:06:28.726+0545] {logging_mixin.py:188} INFO - [2024-03-18T12:06:28.726+0545] {dagbag.py:350} ERROR - Failed to import: //home/sarita/Documents/apache-airflow-project/dags/taxi_metrics_dag.py
Traceback (most recent call last):
  File "/home/sarita/Documents/ETLapp/pythonProject/.venv/lib/python3.9/site-packages/airflow/models/dagbag.py", line 346, in parse
    loader.exec_module(new_module)
  File "<frozen importlib._bootstrap_external>", line 855, in exec_module
  File "<frozen importlib._bootstrap>", line 228, in _call_with_frames_removed
  File "//home/sarita/Documents/apache-airflow-project/dags/taxi_metrics_dag.py", line 11, in <module>
    from db_connection import BATCH_SIZE, get_sqlite_connection, get_clickhouse_connection, SQLITE_TABLE
ModuleNotFoundError: No module named 'db_connection'
[2024-03-18T12:06:28.726+0545] {processor.py:842} WARNING - No viable dags retrieved from //home/sarita/Documents/apache-airflow-project/dags/taxi_metrics_dag.py
[2024-03-18T12:06:28.740+0545] {processor.py:183} INFO - Processing //home/sarita/Documents/apache-airflow-project/dags/taxi_metrics_dag.py took 0.021 seconds
[2024-03-18T12:07:25.339+0545] {processor.py:161} INFO - Started process (PID=18543) to work on //home/sarita/Documents/apache-airflow-project/dags/taxi_metrics_dag.py
[2024-03-18T12:07:25.342+0545] {processor.py:830} INFO - Processing file //home/sarita/Documents/apache-airflow-project/dags/taxi_metrics_dag.py for tasks to queue
[2024-03-18T12:07:25.342+0545] {logging_mixin.py:188} INFO - [2024-03-18T12:07:25.342+0545] {dagbag.py:540} INFO - Filling up the DagBag from //home/sarita/Documents/apache-airflow-project/dags/taxi_metrics_dag.py
[2024-03-18T12:07:25.345+0545] {logging_mixin.py:188} INFO - [2024-03-18T12:07:25.344+0545] {dagbag.py:350} ERROR - Failed to import: //home/sarita/Documents/apache-airflow-project/dags/taxi_metrics_dag.py
Traceback (most recent call last):
  File "/home/sarita/Documents/ETLapp/pythonProject/.venv/lib/python3.9/site-packages/airflow/models/dagbag.py", line 346, in parse
    loader.exec_module(new_module)
  File "<frozen importlib._bootstrap_external>", line 855, in exec_module
  File "<frozen importlib._bootstrap>", line 228, in _call_with_frames_removed
  File "//home/sarita/Documents/apache-airflow-project/dags/taxi_metrics_dag.py", line 11, in <module>
    from db_connection import BATCH_SIZE, get_sqlite_connection, get_clickhouse_connection, SQLITE_TABLE
ModuleNotFoundError: No module named 'db_connection'
[2024-03-18T12:07:25.345+0545] {processor.py:842} WARNING - No viable dags retrieved from //home/sarita/Documents/apache-airflow-project/dags/taxi_metrics_dag.py
[2024-03-18T12:07:25.358+0545] {processor.py:183} INFO - Processing //home/sarita/Documents/apache-airflow-project/dags/taxi_metrics_dag.py took 0.020 seconds
[2024-03-18T12:08:22.106+0545] {processor.py:161} INFO - Started process (PID=18605) to work on //home/sarita/Documents/apache-airflow-project/dags/taxi_metrics_dag.py
[2024-03-18T12:08:22.110+0545] {processor.py:830} INFO - Processing file //home/sarita/Documents/apache-airflow-project/dags/taxi_metrics_dag.py for tasks to queue
[2024-03-18T12:08:22.112+0545] {logging_mixin.py:188} INFO - [2024-03-18T12:08:22.111+0545] {dagbag.py:540} INFO - Filling up the DagBag from //home/sarita/Documents/apache-airflow-project/dags/taxi_metrics_dag.py
[2024-03-18T12:08:22.121+0545] {logging_mixin.py:188} INFO - [2024-03-18T12:08:22.119+0545] {dagbag.py:350} ERROR - Failed to import: //home/sarita/Documents/apache-airflow-project/dags/taxi_metrics_dag.py
Traceback (most recent call last):
  File "/home/sarita/Documents/ETLapp/pythonProject/.venv/lib/python3.9/site-packages/airflow/models/dagbag.py", line 346, in parse
    loader.exec_module(new_module)
  File "<frozen importlib._bootstrap_external>", line 855, in exec_module
  File "<frozen importlib._bootstrap>", line 228, in _call_with_frames_removed
  File "//home/sarita/Documents/apache-airflow-project/dags/taxi_metrics_dag.py", line 11, in <module>
    from db_connection import BATCH_SIZE, get_sqlite_connection, get_clickhouse_connection, SQLITE_TABLE
ModuleNotFoundError: No module named 'db_connection'
[2024-03-18T12:08:22.122+0545] {processor.py:842} WARNING - No viable dags retrieved from //home/sarita/Documents/apache-airflow-project/dags/taxi_metrics_dag.py
[2024-03-18T12:08:22.144+0545] {processor.py:183} INFO - Processing //home/sarita/Documents/apache-airflow-project/dags/taxi_metrics_dag.py took 0.045 seconds
[2024-03-18T12:09:13.280+0545] {processor.py:161} INFO - Started process (PID=18662) to work on //home/sarita/Documents/apache-airflow-project/dags/taxi_metrics_dag.py
[2024-03-18T12:09:13.282+0545] {processor.py:830} INFO - Processing file //home/sarita/Documents/apache-airflow-project/dags/taxi_metrics_dag.py for tasks to queue
[2024-03-18T12:09:13.283+0545] {logging_mixin.py:188} INFO - [2024-03-18T12:09:13.283+0545] {dagbag.py:540} INFO - Filling up the DagBag from //home/sarita/Documents/apache-airflow-project/dags/taxi_metrics_dag.py
[2024-03-18T12:09:13.286+0545] {logging_mixin.py:188} INFO - [2024-03-18T12:09:13.285+0545] {dagbag.py:350} ERROR - Failed to import: //home/sarita/Documents/apache-airflow-project/dags/taxi_metrics_dag.py
Traceback (most recent call last):
  File "/home/sarita/Documents/ETLapp/pythonProject/.venv/lib/python3.9/site-packages/airflow/models/dagbag.py", line 346, in parse
    loader.exec_module(new_module)
  File "<frozen importlib._bootstrap_external>", line 855, in exec_module
  File "<frozen importlib._bootstrap>", line 228, in _call_with_frames_removed
  File "//home/sarita/Documents/apache-airflow-project/dags/taxi_metrics_dag.py", line 11, in <module>
    from db_connection import BATCH_SIZE, get_sqlite_connection, get_clickhouse_connection, SQLITE_TABLE
ModuleNotFoundError: No module named 'db_connection'
[2024-03-18T12:09:13.286+0545] {processor.py:842} WARNING - No viable dags retrieved from //home/sarita/Documents/apache-airflow-project/dags/taxi_metrics_dag.py
[2024-03-18T12:09:13.301+0545] {processor.py:183} INFO - Processing //home/sarita/Documents/apache-airflow-project/dags/taxi_metrics_dag.py took 0.023 seconds
[2024-03-18T12:10:04.830+0545] {processor.py:161} INFO - Started process (PID=18718) to work on //home/sarita/Documents/apache-airflow-project/dags/taxi_metrics_dag.py
[2024-03-18T12:10:04.832+0545] {processor.py:830} INFO - Processing file //home/sarita/Documents/apache-airflow-project/dags/taxi_metrics_dag.py for tasks to queue
[2024-03-18T12:10:04.833+0545] {logging_mixin.py:188} INFO - [2024-03-18T12:10:04.833+0545] {dagbag.py:540} INFO - Filling up the DagBag from //home/sarita/Documents/apache-airflow-project/dags/taxi_metrics_dag.py
[2024-03-18T12:10:04.835+0545] {logging_mixin.py:188} INFO - [2024-03-18T12:10:04.835+0545] {dagbag.py:350} ERROR - Failed to import: //home/sarita/Documents/apache-airflow-project/dags/taxi_metrics_dag.py
Traceback (most recent call last):
  File "/home/sarita/Documents/ETLapp/pythonProject/.venv/lib/python3.9/site-packages/airflow/models/dagbag.py", line 346, in parse
    loader.exec_module(new_module)
  File "<frozen importlib._bootstrap_external>", line 855, in exec_module
  File "<frozen importlib._bootstrap>", line 228, in _call_with_frames_removed
  File "//home/sarita/Documents/apache-airflow-project/dags/taxi_metrics_dag.py", line 11, in <module>
    from db_connection import BATCH_SIZE, get_sqlite_connection, get_clickhouse_connection, SQLITE_TABLE
ModuleNotFoundError: No module named 'db_connection'
[2024-03-18T12:10:04.836+0545] {processor.py:842} WARNING - No viable dags retrieved from //home/sarita/Documents/apache-airflow-project/dags/taxi_metrics_dag.py
[2024-03-18T12:10:04.851+0545] {processor.py:183} INFO - Processing //home/sarita/Documents/apache-airflow-project/dags/taxi_metrics_dag.py took 0.023 seconds
[2024-03-18T12:10:59.450+0545] {processor.py:161} INFO - Started process (PID=18779) to work on //home/sarita/Documents/apache-airflow-project/dags/taxi_metrics_dag.py
[2024-03-18T12:10:59.452+0545] {processor.py:830} INFO - Processing file //home/sarita/Documents/apache-airflow-project/dags/taxi_metrics_dag.py for tasks to queue
[2024-03-18T12:10:59.452+0545] {logging_mixin.py:188} INFO - [2024-03-18T12:10:59.452+0545] {dagbag.py:540} INFO - Filling up the DagBag from //home/sarita/Documents/apache-airflow-project/dags/taxi_metrics_dag.py
[2024-03-18T12:10:59.455+0545] {logging_mixin.py:188} INFO - [2024-03-18T12:10:59.454+0545] {dagbag.py:350} ERROR - Failed to import: //home/sarita/Documents/apache-airflow-project/dags/taxi_metrics_dag.py
Traceback (most recent call last):
  File "/home/sarita/Documents/ETLapp/pythonProject/.venv/lib/python3.9/site-packages/airflow/models/dagbag.py", line 346, in parse
    loader.exec_module(new_module)
  File "<frozen importlib._bootstrap_external>", line 855, in exec_module
  File "<frozen importlib._bootstrap>", line 228, in _call_with_frames_removed
  File "//home/sarita/Documents/apache-airflow-project/dags/taxi_metrics_dag.py", line 11, in <module>
    from db_connection import BATCH_SIZE, get_sqlite_connection, get_clickhouse_connection, SQLITE_TABLE
ModuleNotFoundError: No module named 'db_connection'
[2024-03-18T12:10:59.455+0545] {processor.py:842} WARNING - No viable dags retrieved from //home/sarita/Documents/apache-airflow-project/dags/taxi_metrics_dag.py
[2024-03-18T12:10:59.470+0545] {processor.py:183} INFO - Processing //home/sarita/Documents/apache-airflow-project/dags/taxi_metrics_dag.py took 0.022 seconds
[2024-03-18T12:11:58.113+0545] {processor.py:161} INFO - Started process (PID=18844) to work on //home/sarita/Documents/apache-airflow-project/dags/taxi_metrics_dag.py
[2024-03-18T12:11:58.115+0545] {processor.py:830} INFO - Processing file //home/sarita/Documents/apache-airflow-project/dags/taxi_metrics_dag.py for tasks to queue
[2024-03-18T12:11:58.116+0545] {logging_mixin.py:188} INFO - [2024-03-18T12:11:58.116+0545] {dagbag.py:540} INFO - Filling up the DagBag from //home/sarita/Documents/apache-airflow-project/dags/taxi_metrics_dag.py
[2024-03-18T12:11:58.119+0545] {logging_mixin.py:188} INFO - [2024-03-18T12:11:58.118+0545] {dagbag.py:350} ERROR - Failed to import: //home/sarita/Documents/apache-airflow-project/dags/taxi_metrics_dag.py
Traceback (most recent call last):
  File "/home/sarita/Documents/ETLapp/pythonProject/.venv/lib/python3.9/site-packages/airflow/models/dagbag.py", line 346, in parse
    loader.exec_module(new_module)
  File "<frozen importlib._bootstrap_external>", line 855, in exec_module
  File "<frozen importlib._bootstrap>", line 228, in _call_with_frames_removed
  File "//home/sarita/Documents/apache-airflow-project/dags/taxi_metrics_dag.py", line 11, in <module>
    from db_connection import BATCH_SIZE, get_sqlite_connection, get_clickhouse_connection, SQLITE_TABLE
ModuleNotFoundError: No module named 'db_connection'
[2024-03-18T12:11:58.119+0545] {processor.py:842} WARNING - No viable dags retrieved from //home/sarita/Documents/apache-airflow-project/dags/taxi_metrics_dag.py
[2024-03-18T12:11:58.134+0545] {processor.py:183} INFO - Processing //home/sarita/Documents/apache-airflow-project/dags/taxi_metrics_dag.py took 0.023 seconds
[2024-03-18T12:12:55.285+0545] {processor.py:161} INFO - Started process (PID=18903) to work on //home/sarita/Documents/apache-airflow-project/dags/taxi_metrics_dag.py
[2024-03-18T12:12:55.287+0545] {processor.py:830} INFO - Processing file //home/sarita/Documents/apache-airflow-project/dags/taxi_metrics_dag.py for tasks to queue
[2024-03-18T12:12:55.288+0545] {logging_mixin.py:188} INFO - [2024-03-18T12:12:55.288+0545] {dagbag.py:540} INFO - Filling up the DagBag from //home/sarita/Documents/apache-airflow-project/dags/taxi_metrics_dag.py
[2024-03-18T12:12:55.291+0545] {logging_mixin.py:188} INFO - [2024-03-18T12:12:55.290+0545] {dagbag.py:350} ERROR - Failed to import: //home/sarita/Documents/apache-airflow-project/dags/taxi_metrics_dag.py
Traceback (most recent call last):
  File "/home/sarita/Documents/ETLapp/pythonProject/.venv/lib/python3.9/site-packages/airflow/models/dagbag.py", line 346, in parse
    loader.exec_module(new_module)
  File "<frozen importlib._bootstrap_external>", line 855, in exec_module
  File "<frozen importlib._bootstrap>", line 228, in _call_with_frames_removed
  File "//home/sarita/Documents/apache-airflow-project/dags/taxi_metrics_dag.py", line 11, in <module>
    from db_connection import BATCH_SIZE, get_sqlite_connection, get_clickhouse_connection, SQLITE_TABLE
ModuleNotFoundError: No module named 'db_connection'
[2024-03-18T12:12:55.291+0545] {processor.py:842} WARNING - No viable dags retrieved from //home/sarita/Documents/apache-airflow-project/dags/taxi_metrics_dag.py
[2024-03-18T12:12:55.305+0545] {processor.py:183} INFO - Processing //home/sarita/Documents/apache-airflow-project/dags/taxi_metrics_dag.py took 0.022 seconds
[2024-03-18T12:13:51.056+0545] {processor.py:161} INFO - Started process (PID=18968) to work on //home/sarita/Documents/apache-airflow-project/dags/taxi_metrics_dag.py
[2024-03-18T12:13:51.058+0545] {processor.py:830} INFO - Processing file //home/sarita/Documents/apache-airflow-project/dags/taxi_metrics_dag.py for tasks to queue
[2024-03-18T12:13:51.059+0545] {logging_mixin.py:188} INFO - [2024-03-18T12:13:51.059+0545] {dagbag.py:540} INFO - Filling up the DagBag from //home/sarita/Documents/apache-airflow-project/dags/taxi_metrics_dag.py
[2024-03-18T12:13:51.061+0545] {logging_mixin.py:188} INFO - [2024-03-18T12:13:51.061+0545] {dagbag.py:350} ERROR - Failed to import: //home/sarita/Documents/apache-airflow-project/dags/taxi_metrics_dag.py
Traceback (most recent call last):
  File "/home/sarita/Documents/ETLapp/pythonProject/.venv/lib/python3.9/site-packages/airflow/models/dagbag.py", line 346, in parse
    loader.exec_module(new_module)
  File "<frozen importlib._bootstrap_external>", line 855, in exec_module
  File "<frozen importlib._bootstrap>", line 228, in _call_with_frames_removed
  File "//home/sarita/Documents/apache-airflow-project/dags/taxi_metrics_dag.py", line 11, in <module>
    from db_connection import BATCH_SIZE, get_sqlite_connection, get_clickhouse_connection, SQLITE_TABLE
ModuleNotFoundError: No module named 'db_connection'
[2024-03-18T12:13:51.062+0545] {processor.py:842} WARNING - No viable dags retrieved from //home/sarita/Documents/apache-airflow-project/dags/taxi_metrics_dag.py
[2024-03-18T12:13:51.075+0545] {processor.py:183} INFO - Processing //home/sarita/Documents/apache-airflow-project/dags/taxi_metrics_dag.py took 0.022 seconds
[2024-03-18T12:14:47.340+0545] {processor.py:161} INFO - Started process (PID=19100) to work on //home/sarita/Documents/apache-airflow-project/dags/taxi_metrics_dag.py
[2024-03-18T12:14:47.344+0545] {processor.py:830} INFO - Processing file //home/sarita/Documents/apache-airflow-project/dags/taxi_metrics_dag.py for tasks to queue
[2024-03-18T12:14:47.347+0545] {logging_mixin.py:188} INFO - [2024-03-18T12:14:47.346+0545] {dagbag.py:540} INFO - Filling up the DagBag from //home/sarita/Documents/apache-airflow-project/dags/taxi_metrics_dag.py
[2024-03-18T12:14:47.357+0545] {logging_mixin.py:188} INFO - [2024-03-18T12:14:47.354+0545] {dagbag.py:350} ERROR - Failed to import: //home/sarita/Documents/apache-airflow-project/dags/taxi_metrics_dag.py
Traceback (most recent call last):
  File "/home/sarita/Documents/ETLapp/pythonProject/.venv/lib/python3.9/site-packages/airflow/models/dagbag.py", line 346, in parse
    loader.exec_module(new_module)
  File "<frozen importlib._bootstrap_external>", line 855, in exec_module
  File "<frozen importlib._bootstrap>", line 228, in _call_with_frames_removed
  File "//home/sarita/Documents/apache-airflow-project/dags/taxi_metrics_dag.py", line 11, in <module>
    from db_connection import BATCH_SIZE, get_sqlite_connection, get_clickhouse_connection, SQLITE_TABLE
ModuleNotFoundError: No module named 'db_connection'
[2024-03-18T12:14:47.358+0545] {processor.py:842} WARNING - No viable dags retrieved from //home/sarita/Documents/apache-airflow-project/dags/taxi_metrics_dag.py
[2024-03-18T12:14:47.379+0545] {processor.py:183} INFO - Processing //home/sarita/Documents/apache-airflow-project/dags/taxi_metrics_dag.py took 0.046 seconds
[2024-03-18T12:15:42.859+0545] {processor.py:161} INFO - Started process (PID=19174) to work on //home/sarita/Documents/apache-airflow-project/dags/taxi_metrics_dag.py
[2024-03-18T12:15:42.863+0545] {processor.py:830} INFO - Processing file //home/sarita/Documents/apache-airflow-project/dags/taxi_metrics_dag.py for tasks to queue
[2024-03-18T12:15:42.865+0545] {logging_mixin.py:188} INFO - [2024-03-18T12:15:42.864+0545] {dagbag.py:540} INFO - Filling up the DagBag from //home/sarita/Documents/apache-airflow-project/dags/taxi_metrics_dag.py
[2024-03-18T12:15:42.875+0545] {logging_mixin.py:188} INFO - [2024-03-18T12:15:42.873+0545] {dagbag.py:350} ERROR - Failed to import: //home/sarita/Documents/apache-airflow-project/dags/taxi_metrics_dag.py
Traceback (most recent call last):
  File "/home/sarita/Documents/ETLapp/pythonProject/.venv/lib/python3.9/site-packages/airflow/models/dagbag.py", line 346, in parse
    loader.exec_module(new_module)
  File "<frozen importlib._bootstrap_external>", line 855, in exec_module
  File "<frozen importlib._bootstrap>", line 228, in _call_with_frames_removed
  File "//home/sarita/Documents/apache-airflow-project/dags/taxi_metrics_dag.py", line 11, in <module>
    from db_connection import BATCH_SIZE, get_sqlite_connection, get_clickhouse_connection, SQLITE_TABLE
ModuleNotFoundError: No module named 'db_connection'
[2024-03-18T12:15:42.875+0545] {processor.py:842} WARNING - No viable dags retrieved from //home/sarita/Documents/apache-airflow-project/dags/taxi_metrics_dag.py
[2024-03-18T12:15:42.897+0545] {processor.py:183} INFO - Processing //home/sarita/Documents/apache-airflow-project/dags/taxi_metrics_dag.py took 0.046 seconds
[2024-03-18T12:16:38.022+0545] {processor.py:161} INFO - Started process (PID=19484) to work on //home/sarita/Documents/apache-airflow-project/dags/taxi_metrics_dag.py
[2024-03-18T12:16:38.026+0545] {processor.py:830} INFO - Processing file //home/sarita/Documents/apache-airflow-project/dags/taxi_metrics_dag.py for tasks to queue
[2024-03-18T12:16:38.028+0545] {logging_mixin.py:188} INFO - [2024-03-18T12:16:38.027+0545] {dagbag.py:540} INFO - Filling up the DagBag from //home/sarita/Documents/apache-airflow-project/dags/taxi_metrics_dag.py
[2024-03-18T12:16:38.036+0545] {logging_mixin.py:188} INFO - [2024-03-18T12:16:38.035+0545] {dagbag.py:350} ERROR - Failed to import: //home/sarita/Documents/apache-airflow-project/dags/taxi_metrics_dag.py
Traceback (most recent call last):
  File "/home/sarita/Documents/ETLapp/pythonProject/.venv/lib/python3.9/site-packages/airflow/models/dagbag.py", line 346, in parse
    loader.exec_module(new_module)
  File "<frozen importlib._bootstrap_external>", line 855, in exec_module
  File "<frozen importlib._bootstrap>", line 228, in _call_with_frames_removed
  File "//home/sarita/Documents/apache-airflow-project/dags/taxi_metrics_dag.py", line 11, in <module>
    from db_connection import BATCH_SIZE, get_sqlite_connection, get_clickhouse_connection, SQLITE_TABLE
ModuleNotFoundError: No module named 'db_connection'
[2024-03-18T12:16:38.037+0545] {processor.py:842} WARNING - No viable dags retrieved from //home/sarita/Documents/apache-airflow-project/dags/taxi_metrics_dag.py
[2024-03-18T12:16:38.057+0545] {processor.py:183} INFO - Processing //home/sarita/Documents/apache-airflow-project/dags/taxi_metrics_dag.py took 0.042 seconds
[2024-03-18T12:17:37.212+0545] {processor.py:161} INFO - Started process (PID=19599) to work on //home/sarita/Documents/apache-airflow-project/dags/taxi_metrics_dag.py
[2024-03-18T12:17:37.215+0545] {processor.py:830} INFO - Processing file //home/sarita/Documents/apache-airflow-project/dags/taxi_metrics_dag.py for tasks to queue
[2024-03-18T12:17:37.216+0545] {logging_mixin.py:188} INFO - [2024-03-18T12:17:37.215+0545] {dagbag.py:540} INFO - Filling up the DagBag from //home/sarita/Documents/apache-airflow-project/dags/taxi_metrics_dag.py
[2024-03-18T12:17:37.220+0545] {logging_mixin.py:188} INFO - [2024-03-18T12:17:37.219+0545] {dagbag.py:350} ERROR - Failed to import: //home/sarita/Documents/apache-airflow-project/dags/taxi_metrics_dag.py
Traceback (most recent call last):
  File "/home/sarita/Documents/ETLapp/pythonProject/.venv/lib/python3.9/site-packages/airflow/models/dagbag.py", line 346, in parse
    loader.exec_module(new_module)
  File "<frozen importlib._bootstrap_external>", line 855, in exec_module
  File "<frozen importlib._bootstrap>", line 228, in _call_with_frames_removed
  File "//home/sarita/Documents/apache-airflow-project/dags/taxi_metrics_dag.py", line 11, in <module>
    from db_connection import BATCH_SIZE, get_sqlite_connection, get_clickhouse_connection, SQLITE_TABLE
ModuleNotFoundError: No module named 'db_connection'
[2024-03-18T12:17:37.220+0545] {processor.py:842} WARNING - No viable dags retrieved from //home/sarita/Documents/apache-airflow-project/dags/taxi_metrics_dag.py
[2024-03-18T12:17:37.241+0545] {processor.py:183} INFO - Processing //home/sarita/Documents/apache-airflow-project/dags/taxi_metrics_dag.py took 0.031 seconds
[2024-03-18T12:18:35.758+0545] {processor.py:161} INFO - Started process (PID=19695) to work on //home/sarita/Documents/apache-airflow-project/dags/taxi_metrics_dag.py
[2024-03-18T12:18:35.761+0545] {processor.py:830} INFO - Processing file //home/sarita/Documents/apache-airflow-project/dags/taxi_metrics_dag.py for tasks to queue
[2024-03-18T12:18:35.763+0545] {logging_mixin.py:188} INFO - [2024-03-18T12:18:35.762+0545] {dagbag.py:540} INFO - Filling up the DagBag from //home/sarita/Documents/apache-airflow-project/dags/taxi_metrics_dag.py
[2024-03-18T12:18:35.769+0545] {logging_mixin.py:188} INFO - [2024-03-18T12:18:35.768+0545] {dagbag.py:350} ERROR - Failed to import: //home/sarita/Documents/apache-airflow-project/dags/taxi_metrics_dag.py
Traceback (most recent call last):
  File "/home/sarita/Documents/ETLapp/pythonProject/.venv/lib/python3.9/site-packages/airflow/models/dagbag.py", line 346, in parse
    loader.exec_module(new_module)
  File "<frozen importlib._bootstrap_external>", line 855, in exec_module
  File "<frozen importlib._bootstrap>", line 228, in _call_with_frames_removed
  File "//home/sarita/Documents/apache-airflow-project/dags/taxi_metrics_dag.py", line 11, in <module>
    from db_connection import BATCH_SIZE, get_sqlite_connection, get_clickhouse_connection, SQLITE_TABLE
ModuleNotFoundError: No module named 'db_connection'
[2024-03-18T12:18:35.770+0545] {processor.py:842} WARNING - No viable dags retrieved from //home/sarita/Documents/apache-airflow-project/dags/taxi_metrics_dag.py
[2024-03-18T12:18:35.797+0545] {processor.py:183} INFO - Processing //home/sarita/Documents/apache-airflow-project/dags/taxi_metrics_dag.py took 0.043 seconds
[2024-03-18T12:19:31.007+0545] {processor.py:161} INFO - Started process (PID=19758) to work on //home/sarita/Documents/apache-airflow-project/dags/taxi_metrics_dag.py
[2024-03-18T12:19:31.008+0545] {processor.py:830} INFO - Processing file //home/sarita/Documents/apache-airflow-project/dags/taxi_metrics_dag.py for tasks to queue
[2024-03-18T12:19:31.009+0545] {logging_mixin.py:188} INFO - [2024-03-18T12:19:31.008+0545] {dagbag.py:540} INFO - Filling up the DagBag from //home/sarita/Documents/apache-airflow-project/dags/taxi_metrics_dag.py
[2024-03-18T12:19:31.011+0545] {logging_mixin.py:188} INFO - [2024-03-18T12:19:31.010+0545] {dagbag.py:350} ERROR - Failed to import: //home/sarita/Documents/apache-airflow-project/dags/taxi_metrics_dag.py
Traceback (most recent call last):
  File "/home/sarita/Documents/ETLapp/pythonProject/.venv/lib/python3.9/site-packages/airflow/models/dagbag.py", line 346, in parse
    loader.exec_module(new_module)
  File "<frozen importlib._bootstrap_external>", line 855, in exec_module
  File "<frozen importlib._bootstrap>", line 228, in _call_with_frames_removed
  File "//home/sarita/Documents/apache-airflow-project/dags/taxi_metrics_dag.py", line 11, in <module>
    from db_connection import BATCH_SIZE, get_sqlite_connection, get_clickhouse_connection, SQLITE_TABLE
ModuleNotFoundError: No module named 'db_connection'
[2024-03-18T12:19:31.011+0545] {processor.py:842} WARNING - No viable dags retrieved from //home/sarita/Documents/apache-airflow-project/dags/taxi_metrics_dag.py
[2024-03-18T12:19:31.025+0545] {processor.py:183} INFO - Processing //home/sarita/Documents/apache-airflow-project/dags/taxi_metrics_dag.py took 0.020 seconds
[2024-03-18T12:20:24.128+0545] {processor.py:161} INFO - Started process (PID=19823) to work on //home/sarita/Documents/apache-airflow-project/dags/taxi_metrics_dag.py
[2024-03-18T12:20:24.130+0545] {processor.py:830} INFO - Processing file //home/sarita/Documents/apache-airflow-project/dags/taxi_metrics_dag.py for tasks to queue
[2024-03-18T12:20:24.131+0545] {logging_mixin.py:188} INFO - [2024-03-18T12:20:24.131+0545] {dagbag.py:540} INFO - Filling up the DagBag from //home/sarita/Documents/apache-airflow-project/dags/taxi_metrics_dag.py
[2024-03-18T12:20:24.134+0545] {logging_mixin.py:188} INFO - [2024-03-18T12:20:24.133+0545] {dagbag.py:350} ERROR - Failed to import: //home/sarita/Documents/apache-airflow-project/dags/taxi_metrics_dag.py
Traceback (most recent call last):
  File "/home/sarita/Documents/ETLapp/pythonProject/.venv/lib/python3.9/site-packages/airflow/models/dagbag.py", line 346, in parse
    loader.exec_module(new_module)
  File "<frozen importlib._bootstrap_external>", line 855, in exec_module
  File "<frozen importlib._bootstrap>", line 228, in _call_with_frames_removed
  File "//home/sarita/Documents/apache-airflow-project/dags/taxi_metrics_dag.py", line 11, in <module>
    from db_connection import BATCH_SIZE, get_sqlite_connection, get_clickhouse_connection, SQLITE_TABLE
ModuleNotFoundError: No module named 'db_connection'
[2024-03-18T12:20:24.134+0545] {processor.py:842} WARNING - No viable dags retrieved from //home/sarita/Documents/apache-airflow-project/dags/taxi_metrics_dag.py
[2024-03-18T12:20:24.148+0545] {processor.py:183} INFO - Processing //home/sarita/Documents/apache-airflow-project/dags/taxi_metrics_dag.py took 0.022 seconds
[2024-03-18T12:21:22.046+0545] {processor.py:161} INFO - Started process (PID=19889) to work on //home/sarita/Documents/apache-airflow-project/dags/taxi_metrics_dag.py
[2024-03-18T12:21:22.049+0545] {processor.py:830} INFO - Processing file //home/sarita/Documents/apache-airflow-project/dags/taxi_metrics_dag.py for tasks to queue
[2024-03-18T12:21:22.050+0545] {logging_mixin.py:188} INFO - [2024-03-18T12:21:22.049+0545] {dagbag.py:540} INFO - Filling up the DagBag from //home/sarita/Documents/apache-airflow-project/dags/taxi_metrics_dag.py
[2024-03-18T12:21:22.054+0545] {logging_mixin.py:188} INFO - [2024-03-18T12:21:22.053+0545] {dagbag.py:350} ERROR - Failed to import: //home/sarita/Documents/apache-airflow-project/dags/taxi_metrics_dag.py
Traceback (most recent call last):
  File "/home/sarita/Documents/ETLapp/pythonProject/.venv/lib/python3.9/site-packages/airflow/models/dagbag.py", line 346, in parse
    loader.exec_module(new_module)
  File "<frozen importlib._bootstrap_external>", line 855, in exec_module
  File "<frozen importlib._bootstrap>", line 228, in _call_with_frames_removed
  File "//home/sarita/Documents/apache-airflow-project/dags/taxi_metrics_dag.py", line 11, in <module>
    from db_connection import BATCH_SIZE, get_sqlite_connection, get_clickhouse_connection, SQLITE_TABLE
ModuleNotFoundError: No module named 'db_connection'
[2024-03-18T12:21:22.055+0545] {processor.py:842} WARNING - No viable dags retrieved from //home/sarita/Documents/apache-airflow-project/dags/taxi_metrics_dag.py
[2024-03-18T12:21:22.079+0545] {processor.py:183} INFO - Processing //home/sarita/Documents/apache-airflow-project/dags/taxi_metrics_dag.py took 0.037 seconds
[2024-03-18T12:22:12.361+0545] {processor.py:161} INFO - Started process (PID=19956) to work on //home/sarita/Documents/apache-airflow-project/dags/taxi_metrics_dag.py
[2024-03-18T12:22:12.363+0545] {processor.py:830} INFO - Processing file //home/sarita/Documents/apache-airflow-project/dags/taxi_metrics_dag.py for tasks to queue
[2024-03-18T12:22:12.363+0545] {logging_mixin.py:188} INFO - [2024-03-18T12:22:12.363+0545] {dagbag.py:540} INFO - Filling up the DagBag from //home/sarita/Documents/apache-airflow-project/dags/taxi_metrics_dag.py
[2024-03-18T12:22:12.366+0545] {logging_mixin.py:188} INFO - [2024-03-18T12:22:12.365+0545] {dagbag.py:350} ERROR - Failed to import: //home/sarita/Documents/apache-airflow-project/dags/taxi_metrics_dag.py
Traceback (most recent call last):
  File "/home/sarita/Documents/ETLapp/pythonProject/.venv/lib/python3.9/site-packages/airflow/models/dagbag.py", line 346, in parse
    loader.exec_module(new_module)
  File "<frozen importlib._bootstrap_external>", line 855, in exec_module
  File "<frozen importlib._bootstrap>", line 228, in _call_with_frames_removed
  File "//home/sarita/Documents/apache-airflow-project/dags/taxi_metrics_dag.py", line 11, in <module>
    from db_connection import BATCH_SIZE, get_sqlite_connection, get_clickhouse_connection, SQLITE_TABLE
ModuleNotFoundError: No module named 'db_connection'
[2024-03-18T12:22:12.366+0545] {processor.py:842} WARNING - No viable dags retrieved from //home/sarita/Documents/apache-airflow-project/dags/taxi_metrics_dag.py
[2024-03-18T12:22:12.379+0545] {processor.py:183} INFO - Processing //home/sarita/Documents/apache-airflow-project/dags/taxi_metrics_dag.py took 0.020 seconds
[2024-03-18T12:23:08.388+0545] {processor.py:161} INFO - Started process (PID=20057) to work on //home/sarita/Documents/apache-airflow-project/dags/taxi_metrics_dag.py
[2024-03-18T12:23:08.392+0545] {processor.py:830} INFO - Processing file //home/sarita/Documents/apache-airflow-project/dags/taxi_metrics_dag.py for tasks to queue
[2024-03-18T12:23:08.395+0545] {logging_mixin.py:188} INFO - [2024-03-18T12:23:08.394+0545] {dagbag.py:540} INFO - Filling up the DagBag from //home/sarita/Documents/apache-airflow-project/dags/taxi_metrics_dag.py
[2024-03-18T12:23:08.404+0545] {logging_mixin.py:188} INFO - [2024-03-18T12:23:08.402+0545] {dagbag.py:350} ERROR - Failed to import: //home/sarita/Documents/apache-airflow-project/dags/taxi_metrics_dag.py
Traceback (most recent call last):
  File "/home/sarita/Documents/ETLapp/pythonProject/.venv/lib/python3.9/site-packages/airflow/models/dagbag.py", line 346, in parse
    loader.exec_module(new_module)
  File "<frozen importlib._bootstrap_external>", line 855, in exec_module
  File "<frozen importlib._bootstrap>", line 228, in _call_with_frames_removed
  File "//home/sarita/Documents/apache-airflow-project/dags/taxi_metrics_dag.py", line 11, in <module>
    from db_connection import BATCH_SIZE, get_sqlite_connection, get_clickhouse_connection, SQLITE_TABLE
ModuleNotFoundError: No module named 'db_connection'
[2024-03-18T12:23:08.405+0545] {processor.py:842} WARNING - No viable dags retrieved from //home/sarita/Documents/apache-airflow-project/dags/taxi_metrics_dag.py
[2024-03-18T12:23:08.427+0545] {processor.py:183} INFO - Processing //home/sarita/Documents/apache-airflow-project/dags/taxi_metrics_dag.py took 0.046 seconds
[2024-03-18T12:24:09.168+0545] {processor.py:161} INFO - Started process (PID=20142) to work on //home/sarita/Documents/apache-airflow-project/dags/taxi_metrics_dag.py
[2024-03-18T12:24:09.172+0545] {processor.py:830} INFO - Processing file //home/sarita/Documents/apache-airflow-project/dags/taxi_metrics_dag.py for tasks to queue
[2024-03-18T12:24:09.174+0545] {logging_mixin.py:188} INFO - [2024-03-18T12:24:09.174+0545] {dagbag.py:540} INFO - Filling up the DagBag from //home/sarita/Documents/apache-airflow-project/dags/taxi_metrics_dag.py
[2024-03-18T12:24:09.183+0545] {logging_mixin.py:188} INFO - [2024-03-18T12:24:09.181+0545] {dagbag.py:350} ERROR - Failed to import: //home/sarita/Documents/apache-airflow-project/dags/taxi_metrics_dag.py
Traceback (most recent call last):
  File "/home/sarita/Documents/ETLapp/pythonProject/.venv/lib/python3.9/site-packages/airflow/models/dagbag.py", line 346, in parse
    loader.exec_module(new_module)
  File "<frozen importlib._bootstrap_external>", line 855, in exec_module
  File "<frozen importlib._bootstrap>", line 228, in _call_with_frames_removed
  File "//home/sarita/Documents/apache-airflow-project/dags/taxi_metrics_dag.py", line 11, in <module>
    from db_connection import BATCH_SIZE, get_sqlite_connection, get_clickhouse_connection, SQLITE_TABLE
ModuleNotFoundError: No module named 'db_connection'
[2024-03-18T12:24:09.184+0545] {processor.py:842} WARNING - No viable dags retrieved from //home/sarita/Documents/apache-airflow-project/dags/taxi_metrics_dag.py
[2024-03-18T12:24:09.208+0545] {processor.py:183} INFO - Processing //home/sarita/Documents/apache-airflow-project/dags/taxi_metrics_dag.py took 0.047 seconds
[2024-03-18T12:25:05.393+0545] {processor.py:161} INFO - Started process (PID=20252) to work on //home/sarita/Documents/apache-airflow-project/dags/taxi_metrics_dag.py
[2024-03-18T12:25:05.396+0545] {processor.py:830} INFO - Processing file //home/sarita/Documents/apache-airflow-project/dags/taxi_metrics_dag.py for tasks to queue
[2024-03-18T12:25:05.397+0545] {logging_mixin.py:188} INFO - [2024-03-18T12:25:05.396+0545] {dagbag.py:540} INFO - Filling up the DagBag from //home/sarita/Documents/apache-airflow-project/dags/taxi_metrics_dag.py
[2024-03-18T12:25:05.400+0545] {logging_mixin.py:188} INFO - [2024-03-18T12:25:05.399+0545] {dagbag.py:350} ERROR - Failed to import: //home/sarita/Documents/apache-airflow-project/dags/taxi_metrics_dag.py
Traceback (most recent call last):
  File "/home/sarita/Documents/ETLapp/pythonProject/.venv/lib/python3.9/site-packages/airflow/models/dagbag.py", line 346, in parse
    loader.exec_module(new_module)
  File "<frozen importlib._bootstrap_external>", line 855, in exec_module
  File "<frozen importlib._bootstrap>", line 228, in _call_with_frames_removed
  File "//home/sarita/Documents/apache-airflow-project/dags/taxi_metrics_dag.py", line 11, in <module>
    from db_connection import BATCH_SIZE, get_sqlite_connection, get_clickhouse_connection, SQLITE_TABLE
ModuleNotFoundError: No module named 'db_connection'
[2024-03-18T12:25:05.400+0545] {processor.py:842} WARNING - No viable dags retrieved from //home/sarita/Documents/apache-airflow-project/dags/taxi_metrics_dag.py
[2024-03-18T12:25:05.417+0545] {processor.py:183} INFO - Processing //home/sarita/Documents/apache-airflow-project/dags/taxi_metrics_dag.py took 0.026 seconds
[2024-03-18T12:26:03.203+0545] {processor.py:161} INFO - Started process (PID=21628) to work on //home/sarita/Documents/apache-airflow-project/dags/taxi_metrics_dag.py
[2024-03-18T12:26:03.205+0545] {processor.py:830} INFO - Processing file //home/sarita/Documents/apache-airflow-project/dags/taxi_metrics_dag.py for tasks to queue
[2024-03-18T12:26:03.206+0545] {logging_mixin.py:188} INFO - [2024-03-18T12:26:03.205+0545] {dagbag.py:540} INFO - Filling up the DagBag from //home/sarita/Documents/apache-airflow-project/dags/taxi_metrics_dag.py
[2024-03-18T12:26:03.208+0545] {logging_mixin.py:188} INFO - [2024-03-18T12:26:03.208+0545] {dagbag.py:350} ERROR - Failed to import: //home/sarita/Documents/apache-airflow-project/dags/taxi_metrics_dag.py
Traceback (most recent call last):
  File "/home/sarita/Documents/ETLapp/pythonProject/.venv/lib/python3.9/site-packages/airflow/models/dagbag.py", line 346, in parse
    loader.exec_module(new_module)
  File "<frozen importlib._bootstrap_external>", line 855, in exec_module
  File "<frozen importlib._bootstrap>", line 228, in _call_with_frames_removed
  File "//home/sarita/Documents/apache-airflow-project/dags/taxi_metrics_dag.py", line 11, in <module>
    from db_connection import BATCH_SIZE, get_sqlite_connection, get_clickhouse_connection, SQLITE_TABLE
ModuleNotFoundError: No module named 'db_connection'
[2024-03-18T12:26:03.209+0545] {processor.py:842} WARNING - No viable dags retrieved from //home/sarita/Documents/apache-airflow-project/dags/taxi_metrics_dag.py
[2024-03-18T12:26:03.224+0545] {processor.py:183} INFO - Processing //home/sarita/Documents/apache-airflow-project/dags/taxi_metrics_dag.py took 0.024 seconds
[2024-03-18T12:27:01.728+0545] {processor.py:161} INFO - Started process (PID=23585) to work on //home/sarita/Documents/apache-airflow-project/dags/taxi_metrics_dag.py
[2024-03-18T12:27:01.732+0545] {processor.py:830} INFO - Processing file //home/sarita/Documents/apache-airflow-project/dags/taxi_metrics_dag.py for tasks to queue
[2024-03-18T12:27:01.735+0545] {logging_mixin.py:188} INFO - [2024-03-18T12:27:01.734+0545] {dagbag.py:540} INFO - Filling up the DagBag from //home/sarita/Documents/apache-airflow-project/dags/taxi_metrics_dag.py
[2024-03-18T12:27:01.743+0545] {logging_mixin.py:188} INFO - [2024-03-18T12:27:01.742+0545] {dagbag.py:350} ERROR - Failed to import: //home/sarita/Documents/apache-airflow-project/dags/taxi_metrics_dag.py
Traceback (most recent call last):
  File "/home/sarita/Documents/ETLapp/pythonProject/.venv/lib/python3.9/site-packages/airflow/models/dagbag.py", line 346, in parse
    loader.exec_module(new_module)
  File "<frozen importlib._bootstrap_external>", line 855, in exec_module
  File "<frozen importlib._bootstrap>", line 228, in _call_with_frames_removed
  File "//home/sarita/Documents/apache-airflow-project/dags/taxi_metrics_dag.py", line 11, in <module>
    from db_connection import BATCH_SIZE, get_sqlite_connection, get_clickhouse_connection, SQLITE_TABLE
ModuleNotFoundError: No module named 'db_connection'
[2024-03-18T12:27:01.744+0545] {processor.py:842} WARNING - No viable dags retrieved from //home/sarita/Documents/apache-airflow-project/dags/taxi_metrics_dag.py
[2024-03-18T12:27:01.764+0545] {processor.py:183} INFO - Processing //home/sarita/Documents/apache-airflow-project/dags/taxi_metrics_dag.py took 0.043 seconds
[2024-03-18T12:28:02.566+0545] {processor.py:161} INFO - Started process (PID=24701) to work on //home/sarita/Documents/apache-airflow-project/dags/taxi_metrics_dag.py
[2024-03-18T12:28:02.569+0545] {processor.py:830} INFO - Processing file //home/sarita/Documents/apache-airflow-project/dags/taxi_metrics_dag.py for tasks to queue
[2024-03-18T12:28:02.571+0545] {logging_mixin.py:188} INFO - [2024-03-18T12:28:02.570+0545] {dagbag.py:540} INFO - Filling up the DagBag from //home/sarita/Documents/apache-airflow-project/dags/taxi_metrics_dag.py
[2024-03-18T12:28:02.578+0545] {logging_mixin.py:188} INFO - [2024-03-18T12:28:02.576+0545] {dagbag.py:350} ERROR - Failed to import: //home/sarita/Documents/apache-airflow-project/dags/taxi_metrics_dag.py
Traceback (most recent call last):
  File "/home/sarita/Documents/ETLapp/pythonProject/.venv/lib/python3.9/site-packages/airflow/models/dagbag.py", line 346, in parse
    loader.exec_module(new_module)
  File "<frozen importlib._bootstrap_external>", line 855, in exec_module
  File "<frozen importlib._bootstrap>", line 228, in _call_with_frames_removed
  File "//home/sarita/Documents/apache-airflow-project/dags/taxi_metrics_dag.py", line 11, in <module>
    from db_connection import BATCH_SIZE, get_sqlite_connection, get_clickhouse_connection, SQLITE_TABLE
ModuleNotFoundError: No module named 'db_connection'
[2024-03-18T12:28:02.578+0545] {processor.py:842} WARNING - No viable dags retrieved from //home/sarita/Documents/apache-airflow-project/dags/taxi_metrics_dag.py
[2024-03-18T12:28:02.601+0545] {processor.py:183} INFO - Processing //home/sarita/Documents/apache-airflow-project/dags/taxi_metrics_dag.py took 0.040 seconds
[2024-03-18T12:29:01.938+0545] {processor.py:161} INFO - Started process (PID=24983) to work on //home/sarita/Documents/apache-airflow-project/dags/taxi_metrics_dag.py
[2024-03-18T12:29:01.940+0545] {processor.py:830} INFO - Processing file //home/sarita/Documents/apache-airflow-project/dags/taxi_metrics_dag.py for tasks to queue
[2024-03-18T12:29:01.940+0545] {logging_mixin.py:188} INFO - [2024-03-18T12:29:01.940+0545] {dagbag.py:540} INFO - Filling up the DagBag from //home/sarita/Documents/apache-airflow-project/dags/taxi_metrics_dag.py
[2024-03-18T12:29:01.943+0545] {logging_mixin.py:188} INFO - [2024-03-18T12:29:01.943+0545] {dagbag.py:350} ERROR - Failed to import: //home/sarita/Documents/apache-airflow-project/dags/taxi_metrics_dag.py
Traceback (most recent call last):
  File "/home/sarita/Documents/ETLapp/pythonProject/.venv/lib/python3.9/site-packages/airflow/models/dagbag.py", line 346, in parse
    loader.exec_module(new_module)
  File "<frozen importlib._bootstrap_external>", line 855, in exec_module
  File "<frozen importlib._bootstrap>", line 228, in _call_with_frames_removed
  File "//home/sarita/Documents/apache-airflow-project/dags/taxi_metrics_dag.py", line 11, in <module>
    from db_connection import BATCH_SIZE, get_sqlite_connection, get_clickhouse_connection, SQLITE_TABLE
ModuleNotFoundError: No module named 'db_connection'
[2024-03-18T12:29:01.944+0545] {processor.py:842} WARNING - No viable dags retrieved from //home/sarita/Documents/apache-airflow-project/dags/taxi_metrics_dag.py
[2024-03-18T12:29:01.959+0545] {processor.py:183} INFO - Processing //home/sarita/Documents/apache-airflow-project/dags/taxi_metrics_dag.py took 0.024 seconds
[2024-03-18T12:29:58.789+0545] {processor.py:161} INFO - Started process (PID=26129) to work on //home/sarita/Documents/apache-airflow-project/dags/taxi_metrics_dag.py
[2024-03-18T12:29:58.793+0545] {processor.py:830} INFO - Processing file //home/sarita/Documents/apache-airflow-project/dags/taxi_metrics_dag.py for tasks to queue
[2024-03-18T12:29:58.796+0545] {logging_mixin.py:188} INFO - [2024-03-18T12:29:58.795+0545] {dagbag.py:540} INFO - Filling up the DagBag from //home/sarita/Documents/apache-airflow-project/dags/taxi_metrics_dag.py
[2024-03-18T12:29:58.805+0545] {logging_mixin.py:188} INFO - [2024-03-18T12:29:58.803+0545] {dagbag.py:350} ERROR - Failed to import: //home/sarita/Documents/apache-airflow-project/dags/taxi_metrics_dag.py
Traceback (most recent call last):
  File "/home/sarita/Documents/ETLapp/pythonProject/.venv/lib/python3.9/site-packages/airflow/models/dagbag.py", line 346, in parse
    loader.exec_module(new_module)
  File "<frozen importlib._bootstrap_external>", line 855, in exec_module
  File "<frozen importlib._bootstrap>", line 228, in _call_with_frames_removed
  File "//home/sarita/Documents/apache-airflow-project/dags/taxi_metrics_dag.py", line 11, in <module>
    from db_connection import BATCH_SIZE, get_sqlite_connection, get_clickhouse_connection, SQLITE_TABLE
ModuleNotFoundError: No module named 'db_connection'
[2024-03-18T12:29:58.806+0545] {processor.py:842} WARNING - No viable dags retrieved from //home/sarita/Documents/apache-airflow-project/dags/taxi_metrics_dag.py
[2024-03-18T12:29:58.830+0545] {processor.py:183} INFO - Processing //home/sarita/Documents/apache-airflow-project/dags/taxi_metrics_dag.py took 0.049 seconds
[2024-03-18T12:30:57.616+0545] {processor.py:161} INFO - Started process (PID=28000) to work on //home/sarita/Documents/apache-airflow-project/dags/taxi_metrics_dag.py
[2024-03-18T12:30:57.619+0545] {processor.py:830} INFO - Processing file //home/sarita/Documents/apache-airflow-project/dags/taxi_metrics_dag.py for tasks to queue
[2024-03-18T12:30:57.621+0545] {logging_mixin.py:188} INFO - [2024-03-18T12:30:57.620+0545] {dagbag.py:540} INFO - Filling up the DagBag from //home/sarita/Documents/apache-airflow-project/dags/taxi_metrics_dag.py
[2024-03-18T12:30:57.627+0545] {logging_mixin.py:188} INFO - [2024-03-18T12:30:57.626+0545] {dagbag.py:350} ERROR - Failed to import: //home/sarita/Documents/apache-airflow-project/dags/taxi_metrics_dag.py
Traceback (most recent call last):
  File "/home/sarita/Documents/ETLapp/pythonProject/.venv/lib/python3.9/site-packages/airflow/models/dagbag.py", line 346, in parse
    loader.exec_module(new_module)
  File "<frozen importlib._bootstrap_external>", line 855, in exec_module
  File "<frozen importlib._bootstrap>", line 228, in _call_with_frames_removed
  File "//home/sarita/Documents/apache-airflow-project/dags/taxi_metrics_dag.py", line 11, in <module>
    from db_connection import BATCH_SIZE, get_sqlite_connection, get_clickhouse_connection, SQLITE_TABLE
ModuleNotFoundError: No module named 'db_connection'
[2024-03-18T12:30:57.628+0545] {processor.py:842} WARNING - No viable dags retrieved from //home/sarita/Documents/apache-airflow-project/dags/taxi_metrics_dag.py
[2024-03-18T12:30:57.651+0545] {processor.py:183} INFO - Processing //home/sarita/Documents/apache-airflow-project/dags/taxi_metrics_dag.py took 0.040 seconds
[2024-03-18T12:31:53.123+0545] {processor.py:161} INFO - Started process (PID=28084) to work on //home/sarita/Documents/apache-airflow-project/dags/taxi_metrics_dag.py
[2024-03-18T12:31:53.126+0545] {processor.py:830} INFO - Processing file //home/sarita/Documents/apache-airflow-project/dags/taxi_metrics_dag.py for tasks to queue
[2024-03-18T12:31:53.127+0545] {logging_mixin.py:188} INFO - [2024-03-18T12:31:53.126+0545] {dagbag.py:540} INFO - Filling up the DagBag from //home/sarita/Documents/apache-airflow-project/dags/taxi_metrics_dag.py
[2024-03-18T12:31:53.130+0545] {logging_mixin.py:188} INFO - [2024-03-18T12:31:53.130+0545] {dagbag.py:350} ERROR - Failed to import: //home/sarita/Documents/apache-airflow-project/dags/taxi_metrics_dag.py
Traceback (most recent call last):
  File "/home/sarita/Documents/ETLapp/pythonProject/.venv/lib/python3.9/site-packages/airflow/models/dagbag.py", line 346, in parse
    loader.exec_module(new_module)
  File "<frozen importlib._bootstrap_external>", line 855, in exec_module
  File "<frozen importlib._bootstrap>", line 228, in _call_with_frames_removed
  File "//home/sarita/Documents/apache-airflow-project/dags/taxi_metrics_dag.py", line 11, in <module>
    from db_connection import BATCH_SIZE, get_sqlite_connection, get_clickhouse_connection, SQLITE_TABLE
ModuleNotFoundError: No module named 'db_connection'
[2024-03-18T12:31:53.131+0545] {processor.py:842} WARNING - No viable dags retrieved from //home/sarita/Documents/apache-airflow-project/dags/taxi_metrics_dag.py
[2024-03-18T12:31:53.150+0545] {processor.py:183} INFO - Processing //home/sarita/Documents/apache-airflow-project/dags/taxi_metrics_dag.py took 0.029 seconds
